Workbook
Name ADRESSE: #REF!
Name COMPTE_TRESORERIE: PARAMETRES!$G$18:$G$29
Name DOCUMENT: PARAMETRES!#REF!
Name ENTITE: PARAMETRES!$A$4:$A$11
Name ID_BC_UNIQUE: 'CARNET CDE FATURE PFO 2025'!$E$6:$E$303
Name ID_BC_UNIQUE: 'CARNET DE COMMANDE'!$D$6:$D$350
Name Montant_BC: 'CARNET CDE FATURE PFO 2025'!$G$5:INDEX('CARNET CDE FATURE PFO 2025'!$F:$F,COUNTA('CARNET CDE FATURE PFO 2025'!$F:$F)+4)
Name Montant_BC: 'CARNET DE COMMANDE'!$I$5:INDEX('CARNET DE COMMANDE'!$E:$E,COUNTA('CARNET DE COMMANDE'!$E:$E)+4)
Name N°_BC: Tableau5[ACTIONS A MENER]
Name N°_BC: #REF!
Name NCC: #REF!
Name Nom_BC: 'CARNET CDE FATURE PFO 2025'!$C$5:INDEX('CARNET CDE FATURE PFO 2025'!$D:$D,COUNTA('CARNET CDE FATURE PFO 2025'!$D:$D)+4)
Name Nom_BC: 'CARNET DE COMMANDE'!#REF!:INDEX('CARNET DE COMMANDE'!#REF!,COUNTA('CARNET DE COMMANDE'!#REF!)+4)
Name NOM_CLIENT: 'CLIENTS-CREANCES'!$B$5:$B$21
Name Nom_TClient: #REF!
Name RAISON: #REF!
Name SIEGE: #REF!
Name SIM_GROUP: PARAMETRES!$A$5:$A$9
Name TELEPHONE: #REF!
Name TYPE_DE_BON_DE_COMMANDE_CLIENT: PARAMETRES!#REF!

Sheet PARAMETRES
G1: CONDITION DE REGLEMENT CLIENTS | K1: ACTION DE RECOUVREMENT
A3: ENTITE | C3: CODE PROJET | D3: PROJET/CHANTIER | G3: CLIENT | H3: CONDITION DE PAIEMENT | I3: N° BC | K3: NOMBRE DE JOUR DE RETARD | L3: ACTIONS A MENER
A4: KENAM S | C4: 654R8002 | D4: VRD UNIVERSITE ODIENNE TX | G4: PFO | H4: 30 JOURS DATE DE RECEPTION | I4: LOCATION ENGIN ACHAT FER BETON, GRAVIER, SABLE | K4: 10 | L4: FAIRE 1ERE RELANCE
A5: BTTP | C5: 006G4101 | D5: ATELIER SONGON CHARGES ACT LOCAT° | G5: KOIRA BTP | H5: 30 JOURS DATE DE RECEPTION | I5: ACHAT FER BETON | K5: 20 | L5: FAIRE 2EME RELANCE
A6: DG_FF | C6: 007G4101 | D6: ATELIER DIVO CHARGE ACT LOC EXT | G6: KOIRA BTP | H6: 15 JOURS MAX DATE DE RECEPTION | I6: LOCATION ENGINN | K6: 35 | L6: FAIRE 3EME RELANCE
C7: 009G4101 | D7: ATELIER BOUAKE CHARGE ACT LOCAT° EXT | G7: AFRIK BETON | H7: 40 JOURS DATE DE RECEPTION | I7: LOCATION CAMION PLATEAU | K7: 60 | L7: OUVRIR UN LITIGE
C8: 010G4101 | D8: ATELIER COTIERE CHARGES ACT LOCAT° EXT | G8: SOGENA
C9: 011G4101 | D9: ATELIER DABAKALA CHARGRES ACT LOC E | G9: M IBRAHIM SALHAB
C10: 015G3114 | D10: ATELIER KONG CHARGE ACT LOCATION | G10: KOIRA SA | H10: 30 JOURS DATE DE RECEPTION | I10: ACHAT FER BETON
C11: 015G4101 | D11: ATELIER KONG CHARGE ACT LOCAT° EXT | G11: BETEC-CI | H11: 30 JOURS DATE DE RECEPTION | K11: INTERVALLE BALANCE
C12: 016G4101 | D12: ATELIER BINGERVILLE SM LOCATION EXTERNES | G12: SCORE | H12: 30 JOURS DATE DE RECEPTION | I12: ACHAT MATERIAUX
C13: 017G4101 | D13: ATELIER PETIT NASS. KT SM LOCAT° | G13: SOGIMAS | K13: NOMBRE DE JOUR DE RETARD | L13: INTERVALLE DE BALANCE | M13: Colonne1
C14: 018G4101 | D14: ATELIER KORHOGO SM LOCATION EXTERNES | K14: 0 | L14: [0;29]
C15: 019G3110 | D15: ATELIER ODIENNE CHARGE FG PRESTATAIRE | L15: 30 | M15: [30;59]
C16: 019G4101 | D16: ATELIER ODIENNE CHARGE ACT LOC EXT | L16: 60 | M16: [60;89]
C17: 019R4101 | D17: ATELIER ODIENNE CHARGE ACT LOC EXT | G17: COMPTE TRESORERIE | H17: TYPE MONNAIE | I17: NATURE DE LA MONNAIE | L17: 90 | M17: [90;120]
C18: 021G4101 | D18: SNA PEDRO SOUBRE LOCATION EXTERNE | G18: BDU | H18: SCRIPTURALE | I18: CHEQUE_VIREMENT_CARTE | L18: 120 | M18: >120
C19: 022G4101 | D19: SOUBRE LOCATION EXTERNES POUR LE SE | G19: BDU | H19: SCRIPTURALE | I19: CHEQUE_VIREMENT_CARTE
C20: 170R2101 | D20: FERMETURE AKOUEDO-TX REMOD V. P. CANNIVEAUX | G20: BICICI | H20: SCRIPTURALE | I20: CHEQUE_VIREMENT_CARTE
C21: 251B0206 | D21: VILLA 20 GROS ŒUVRE MACONNERIE | G21: NSIA | H21: SCRIPTURALE | I21: CHEQUE_VIREMENT_CARTE
C22: 252B0209 | D22: REHAB. TOUR C GROS ŒUVRE M. OE | G22: ECOBANK | H22: SCRIPTURALE | I22: CHEQUE_VIREMENT_CARTE
C23: 252B0402 | D23: REHAB. TOUR C CHARPENTE COUVERTURE M | G23: UBA | H23: FIDUCIAIRE | I23: BILLET_ESPECES | K23: Terminologie correcte selon la situation
C24: 255R1001 | D24: TX PROLONGEMENT BD MITTERAND-INST ENTREP | G24: CAISSE | H24: ELECTRONIQUE | I24: TRANSACTIONS VIA APPLICATION
C25: 255R8002 | D25: TX PROLONGEMENT BD MITTERAND-TX MAD ENGIN | G25: CAISSE | H25: ELECTRONIQUE | I25: TRANSACTIONS VIA APPLICATION | K25: Situation réelle | L25: Terme professionnel
C26: 257B0001 | D26: COMPLEXE RES KONG RES KONG GLE FRS | G26: BDU | K26: Échue et non payée | L26: IMPAYÉE
C27: 257B0003 | D27: COMPLEXE RES KONG GLE INST CHANT | G27: BICICI | K27: Échue et partiellement payée | L27: PARTIELLEMENT IMPAYÉE ou PAIEMENT PARTIEL
C28: 257B0005 | D28: COMPLEXE RES. KONG GLE | G28: NSIA | K28: Non échue | L28: NON ÉCHUE
C29: 257B0101 | D29: COMPLEXE RESIDENTIEL-KONG-AMENAGEMENT EXT TERRASSEMENT | G29: SGCI | K29: Totalement payée | L29: PAYÉE
C30: 257B0104 | D30: COMPLEXE RESIDENTIEL KONG-VRD VOIRIE CHE | K30: Annulée | L30: FACTURE ANNULÉE
C31: 257B0105 | D31: COMPLEXE RES KONG AMENAGT EX RESEA E
C32: 257B0109 | D32: COMPLEXE RES. KONG AMENGT EXT P
C33: 257B0200 | D33: COMPLEXE RESIDENTIEL-KONG GROS ŒUVRE GL
C34: 257B0203 | D34: COMPLEXE RESIDENTIEL KONG-GROS ŒUVRE FONDATION
C35: 257B0206 | D35: COMPLEXE RES. KONG GROS ŒUVRE MACO
C36: 257B0207 | D36: COMPLEXE RESIDENTIEL KONG-GROS ŒUVRE M.O
C37: 257B0209 | D37: COMPLEXE RESIDENTIEL-KONG-GROS ŒUVRE DRAINAGE
C38: 257B0403 | D38: COMPLEXE RESIDENTIEL KONG-CHARPENTE COUVERTURE BOIS-05 VILLAS FAMILLE
C39: 257B0504 | D39: COMPLEXE RES. KONG REVT FASCADES M.
C40: 257B0801 | D40: COMPLEXE RES. KONG CLOISON DOUBLAGE
C41: 261B0200 | D41: MUSEE DE COCODY GROS ŒUVRE GL
...

Sheet CLIENTS-CREANCES
M1: PERIODE DEFINIE | N1: 45658 | O1: 46387
A2: =+"LISTE DES CLIENTS ET DES CREANCES "&YEAR($O$1) -> LISTE DES CLIENTS ET DES CREANCES 2026
A4: ENTITE | B4: NOM CLIENT | C4: CATEGORIE | D4: NUMERO | E4: REGIME FISCALE | F4: BOITE POSTALE | G4: LOCALISATION | H4: TELEPHONE | I4: ACTIVITE | J4: CORRESPONDANT | K4: SOLDE REPORTE | L4: SOLDE N-1 | M4: MONTANT DU | N4: MONTANT RECOUVRE | O4: SOLDE N
A5: KENAM S | B5: AFRIK BETON | C5: ENTREPRISE | F5: 01 BP 5676 ABIDJAN 01 | G5: Abidjan, Yopougon, Zone industrielle, Lots N°14, 14 bis et N°564, Ilot N°56, | H5: 27 21 22 22 21 | L5: =+SUMIFS(Tableau6[NET A PAYER],Tableau6[CLIENT],Tableau1[[#This Row],[NOM CLIENT]],Tableau6[DATE DE FACTURATION],"<"&'CLIENTS-CREANCES'!$N$1)-SUMIFS(Tableau6[MONTANT PAYE],Tableau6[CLIENT],Tableau1[[#This Row],[NOM CLIENT]],Tableau6[DATE DE FACTURATION],"<"&'CLIENTS-CREANCES'!$N$1) -> 0 | M5: =SUMIFS(Tableau6[NET A PAYER],Tableau6[CLIENT],Tableau1[[#This Row],[NOM CLIENT]],Tableau6[DATE DE FACTURATION],">="&'CLIENTS-CREANCES'!$N$1,Tableau6[DATE DE FACTURATION],"<="&'CLIENTS-CREANCES'!$O$1) -> 4519400 | N5: =SUMIFS(Tableau3[MONTANT TTC],Tableau3[CLIENTS],Tableau1[[#This Row],[NOM CLIENT]],Tableau3[[DATE DE PAIEMENT ]],">="&'CLIENTS-CREANCES'!$N$1,Tableau3[[DATE DE PAIEMENT ]],"<="&'CLIENTS-CREANCES'!$O$1) -> 4519400 | O5: =+SUMIFS(Tableau6[NET A PAYER],Tableau6[CLIENT],Tableau1[[#This Row],[NOM CLIENT]],Tableau6[DATE DE DEPOT],"<="&'CLIENTS-CREANCES'!$O$1)-SUMIFS(Tableau3[MONTANT TTC],Tableau3[CLIENTS],Tableau1[[#This Row],[NOM CLIENT]],Tableau3[[DATE DE PAIEMENT ]],"<="&'CLIENTS-CREANCES'!$O$1) -> 0
A6: KENAM S | B6: BETEC-CI | C6: ENTREPRISE | D6: 1600297 K | F6: 16 BP 387 ABIDJAN 16 | G6: SOCOPRIX – RIVIERA TRIANGLE – IMMEUBLE TECHNIBAT 1er Etage | H6: 27 22 54 54 41 | I6: GENIE CIVIL | L6: =+SUMIFS(Tableau6[NET A PAYER],Tableau6[CLIENT],Tableau1[[#This Row],[NOM CLIENT]],Tableau6[DATE DE FACTURATION],"<"&'CLIENTS-CREANCES'!$N$1)-SUMIFS(Tableau6[MONTANT PAYE],Tableau6[CLIENT],Tableau1[[#This Row],[NOM CLIENT]],Tableau6[DATE DE FACTURATION],"<"&'CLIENTS-CREANCES'!$N$1) -> 0 | M6: =SUMIFS(Tableau6[NET A PAYER],Tableau6[CLIENT],Tableau1[[#This Row],[NOM CLIENT]],Tableau6[DATE DE FACTURATION],">="&'CLIENTS-CREANCES'!$N$1,Tableau6[DATE DE FACTURATION],"<="&'CLIENTS-CREANCES'!$O$1) -> 3465070 | N6: =SUMIFS(Tableau3[MONTANT TTC],Tableau3[CLIENTS],Tableau1[[#This Row],[NOM CLIENT]],Tableau3[[DATE DE PAIEMENT ]],">="&'CLIENTS-CREANCES'!$N$1,Tableau3[[DATE DE PAIEMENT ]],"<="&'CLIENTS-CREANCES'!$O$1) -> 3465070 | O6: =+SUMIFS(Tableau6[NET A PAYER],Tableau6[CLIENT],Tableau1[[#This Row],[NOM CLIENT]],Tableau6[DATE DE DEPOT],"<="&'CLIENTS-CREANCES'!$O$1)-SUMIFS(Tableau3[MONTANT TTC],Tableau3[CLIENTS],Tableau1[[#This Row],[NOM CLIENT]],Tableau3[[DATE DE PAIEMENT ]],"<="&'CLIENTS-CREANCES'!$O$1) -> 0
A7: KENAM S | B7: KOIRA BTP | C7: ENTREPRISE | D7: 1924576 J | F7: 03 BP 2176 ABIDJAN 03 | G7: Abidjan, Vridi Rue Pointe des Fumeurs | H7: 27 21 27 49 80/27 21 27 49 81 | I7: GENIE CIVIL | L7: =+SUMIFS(Tableau6[NET A PAYER],Tableau6[CLIENT],Tableau1[[#This Row],[NOM CLIENT]],Tableau6[DATE DE FACTURATION],"<"&'CLIENTS-CREANCES'!$N$1)-SUMIFS(Tableau6[MONTANT PAYE],Tableau6[CLIENT],Tableau1[[#This Row],[NOM CLIENT]],Tableau6[DATE DE FACTURATION],"<"&'CLIENTS-CREANCES'!$N$1) -> 0 | M7: =SUMIFS(Tableau6[NET A PAYER],Tableau6[CLIENT],Tableau1[[#This Row],[NOM CLIENT]],Tableau6[DATE DE FACTURATION],">="&'CLIENTS-CREANCES'!$N$1,Tableau6[DATE DE FACTURATION],"<="&'CLIENTS-CREANCES'!$O$1) -> 207498939 | N7: =SUMIFS(Tableau3[MONTANT TTC],Tableau3[CLIENTS],Tableau1[[#This Row],[NOM CLIENT]],Tableau3[[DATE DE PAIEMENT ]],">="&'CLIENTS-CREANCES'!$N$1,Tableau3[[DATE DE PAIEMENT ]],"<="&'CLIENTS-CREANCES'!$O$1) -> 200572342 | O7: =+SUMIFS(Tableau6[NET A PAYER],Tableau6[CLIENT],Tableau1[[#This Row],[NOM CLIENT]],Tableau6[DATE DE DEPOT],"<="&'CLIENTS-CREANCES'!$O$1)-SUMIFS(Tableau3[MONTANT TTC],Tableau3[CLIENTS],Tableau1[[#This Row],[NOM CLIENT]],Tableau3[[DATE DE PAIEMENT ]],"<="&'CLIENTS-CREANCES'!$O$1) -> 6926597
A8: KENAM S | B8: KOIRA SA | C8: ENTREPRISE | D8: 0818080 A | F8: 03 BP 2176 Abidjan 03 | G8: Rue des Points aux Fumeurs - Zone Industrielle Vridi | H8: 27 21 27 49 81 | I8: Commerce général de produits importés | L8: =+SUMIFS(Tableau6[NET A PAYER],Tableau6[CLIENT],Tableau1[[#This Row],[NOM CLIENT]],Tableau6[DATE DE FACTURATION],"<"&'CLIENTS-CREANCES'!$N$1)-SUMIFS(Tableau6[MONTANT PAYE],Tableau6[CLIENT],Tableau1[[#This Row],[NOM CLIENT]],Tableau6[DATE DE FACTURATION],"<"&'CLIENTS-CREANCES'!$N$1) -> 0 | M8: =SUMIFS(Tableau6[NET A PAYER],Tableau6[CLIENT],Tableau1[[#This Row],[NOM CLIENT]],Tableau6[DATE DE FACTURATION],">="&'CLIENTS-CREANCES'!$N$1,Tableau6[DATE DE FACTURATION],"<="&'CLIENTS-CREANCES'!$O$1) -> 6926600 | N8: =SUMIFS(Tableau3[MONTANT TTC],Tableau3[CLIENTS],Tableau1[[#This Row],[NOM CLIENT]],Tableau3[[DATE DE PAIEMENT ]],">="&'CLIENTS-CREANCES'!$N$1,Tableau3[[DATE DE PAIEMENT ]],"<="&'CLIENTS-CREANCES'!$O$1) -> 6926600 | O8: =+SUMIFS(Tableau6[NET A PAYER],Tableau6[CLIENT],Tableau1[[#This Row],[NOM CLIENT]],Tableau6[DATE DE DEPOT],"<="&'CLIENTS-CREANCES'!$O$1)-SUMIFS(Tableau3[MONTANT TTC],Tableau3[CLIENTS],Tableau1[[#This Row],[NOM CLIENT]],Tableau3[[DATE DE PAIEMENT ]],"<="&'CLIENTS-CREANCES'!$O$1) -> 0
A9: KENAM S | B9: M IBRAHIM SALHAB | C9: PARTICULIER | L9: =+SUMIFS(Tableau6[NET A PAYER],Tableau6[CLIENT],Tableau1[[#This Row],[NOM CLIENT]],Tableau6[DATE DE FACTURATION],"<"&'CLIENTS-CREANCES'!$N$1)-SUMIFS(Tableau6[MONTANT PAYE],Tableau6[CLIENT],Tableau1[[#This Row],[NOM CLIENT]],Tableau6[DATE DE FACTURATION],"<"&'CLIENTS-CREANCES'!$N$1) -> 0 | M9: =SUMIFS(Tableau6[NET A PAYER],Tableau6[CLIENT],Tableau1[[#This Row],[NOM CLIENT]],Tableau6[DATE DE FACTURATION],">="&'CLIENTS-CREANCES'!$N$1,Tableau6[DATE DE FACTURATION],"<="&'CLIENTS-CREANCES'!$O$1) -> 1711838 | N9: =SUMIFS(Tableau3[MONTANT TTC],Tableau3[CLIENTS],Tableau1[[#This Row],[NOM CLIENT]],Tableau3[[DATE DE PAIEMENT ]],">="&'CLIENTS-CREANCES'!$N$1,Tableau3[[DATE DE PAIEMENT ]],"<="&'CLIENTS-CREANCES'!$O$1) -> 1566766.8 | O9: =+SUMIFS(Tableau6[NET A PAYER],Tableau6[CLIENT],Tableau1[[#This Row],[NOM CLIENT]],Tableau6[DATE DE DEPOT],"<="&'CLIENTS-CREANCES'!$O$1)-SUMIFS(Tableau3[MONTANT TTC],Tableau3[CLIENTS],Tableau1[[#This Row],[NOM CLIENT]],Tableau3[[DATE DE PAIEMENT ]],"<="&'CLIENTS-CREANCES'!$O$1) -> 145071.2
A10: KENAM S | B10: PFO CONSTRUCTION | C10: ENTREPRISE | D10: 1205106 C | E10: RNI | F10: 16 BP 387 ABIDJAN 16 | G10: ABIDJAN COCODY BD LATRILLE APRES SODEMI | H10: 27 22 48 45 45 | I10: GENIE CIVIL | L10: =+SUMIFS(Tableau6[NET A PAYER],Tableau6[CLIENT],Tableau1[[#This Row],[NOM CLIENT]],Tableau6[DATE DE FACTURATION],"<"&'CLIENTS-CREANCES'!$N$1)-SUMIFS(Tableau6[MONTANT PAYE],Tableau6[CLIENT],Tableau1[[#This Row],[NOM CLIENT]],Tableau6[DATE DE FACTURATION],"<"&'CLIENTS-CREANCES'!$N$1) -> 0 | M10: =SUMIFS(Tableau6[NET A PAYER],Tableau6[CLIENT],Tableau1[[#This Row],[NOM CLIENT]],Tableau6[DATE DE FACTURATION],">="&'CLIENTS-CREANCES'!$N$1,Tableau6[DATE DE FACTURATION],"<="&'CLIENTS-CREANCES'!$O$1) -> 2341765664 | N10: =SUMIFS(Tableau3[MONTANT TTC],Tableau3[CLIENTS],Tableau1[[#This Row],[NOM CLIENT]],Tableau3[[DATE DE PAIEMENT ]],">="&'CLIENTS-CREANCES'!$N$1,Tableau3[[DATE DE PAIEMENT ]],"<="&'CLIENTS-CREANCES'!$O$1) -> 2470682140 | O10: =+SUMIFS(Tableau6[NET A PAYER],Tableau6[CLIENT],Tableau1[[#This Row],[NOM CLIENT]],Tableau6[DATE DE DEPOT],"<="&'CLIENTS-CREANCES'!$O$1)-SUMIFS(Tableau3[MONTANT TTC],Tableau3[CLIENTS],Tableau1[[#This Row],[NOM CLIENT]],Tableau3[[DATE DE PAIEMENT ]],"<="&'CLIENTS-CREANCES'!$O$1) -> -128916476
A11: KENAM S | B11: SCORE | C11: ENTREPRISE | D11: 1332571 T | G11: Cocody Angré 7ieme Tranche, Abidjan, Cote d'Ivoire | I11: Route et voirie | L11: =+SUMIFS(Tableau6[NET A PAYER],Tableau6[CLIENT],Tableau1[[#This Row],[NOM CLIENT]],Tableau6[DATE DE FACTURATION],"<"&'CLIENTS-CREANCES'!$N$1)-SUMIFS(Tableau6[MONTANT PAYE],Tableau6[CLIENT],Tableau1[[#This Row],[NOM CLIENT]],Tableau6[DATE DE FACTURATION],"<"&'CLIENTS-CREANCES'!$N$1) -> 0 | M11: =SUMIFS(Tableau6[NET A PAYER],Tableau6[CLIENT],Tableau1[[#This Row],[NOM CLIENT]],Tableau6[DATE DE FACTURATION],">="&'CLIENTS-CREANCES'!$N$1,Tableau6[DATE DE FACTURATION],"<="&'CLIENTS-CREANCES'!$O$1) -> 2336400 | N11: =SUMIFS(Tableau3[MONTANT TTC],Tableau3[CLIENTS],Tableau1[[#This Row],[NOM CLIENT]],Tableau3[[DATE DE PAIEMENT ]],">="&'CLIENTS-CREANCES'!$N$1,Tableau3[[DATE DE PAIEMENT ]],"<="&'CLIENTS-CREANCES'!$O$1) -> 2336400 | O11: =+SUMIFS(Tableau6[NET A PAYER],Tableau6[CLIENT],Tableau1[[#This Row],[NOM CLIENT]],Tableau6[DATE DE DEPOT],"<="&'CLIENTS-CREANCES'!$O$1)-SUMIFS(Tableau3[MONTANT TTC],Tableau3[CLIENTS],Tableau1[[#This Row],[NOM CLIENT]],Tableau3[[DATE DE PAIEMENT ]],"<="&'CLIENTS-CREANCES'!$O$1) -> 0
A12: KENAM S | B12: SOGENA | C12: ENTREPRISE | D12: 1750736 P | E12: RNI | F12: 26 BP 1121 Abidjan 26 | G12: Rue des Brasseurs, Imm. Rive Droite, 3ème étage - Zone 3 | H12: 27 21 22 22 21 | L12: =+SUMIFS(Tableau6[NET A PAYER],Tableau6[CLIENT],Tableau1[[#This Row],[NOM CLIENT]],Tableau6[DATE DE FACTURATION],"<"&'CLIENTS-CREANCES'!$N$1)-SUMIFS(Tableau6[MONTANT PAYE],Tableau6[CLIENT],Tableau1[[#This Row],[NOM CLIENT]],Tableau6[DATE DE FACTURATION],"<"&'CLIENTS-CREANCES'!$N$1) -> 0 | M12: =SUMIFS(Tableau6[NET A PAYER],Tableau6[CLIENT],Tableau1[[#This Row],[NOM CLIENT]],Tableau6[DATE DE FACTURATION],">="&'CLIENTS-CREANCES'!$N$1,Tableau6[DATE DE FACTURATION],"<="&'CLIENTS-CREANCES'!$O$1) -> 2112809 | N12: =SUMIFS(Tableau3[MONTANT TTC],Tableau3[CLIENTS],Tableau1[[#This Row],[NOM CLIENT]],Tableau3[[DATE DE PAIEMENT ]],">="&'CLIENTS-CREANCES'!$N$1,Tableau3[[DATE DE PAIEMENT ]],"<="&'CLIENTS-CREANCES'!$O$1) -> 2283074.6 | O12: =+SUMIFS(Tableau6[NET A PAYER],Tableau6[CLIENT],Tableau1[[#This Row],[NOM CLIENT]],Tableau6[DATE DE DEPOT],"<="&'CLIENTS-CREANCES'!$O$1)-SUMIFS(Tableau3[MONTANT TTC],Tableau3[CLIENTS],Tableau1[[#This Row],[NOM CLIENT]],Tableau3[[DATE DE PAIEMENT ]],"<="&'CLIENTS-CREANCES'!$O$1) -> -170265.6
A13: KENAM S | B13: SOGIMAS | C13: ENTREPRISE | L13: =+SUMIFS(Tableau6[NET A PAYER],Tableau6[CLIENT],Tableau1[[#This Row],[NOM CLIENT]],Tableau6[DATE DE FACTURATION],"<"&'CLIENTS-CREANCES'!$N$1)-SUMIFS(Tableau6[MONTANT PAYE],Tableau6[CLIENT],Tableau1[[#This Row],[NOM CLIENT]],Tableau6[DATE DE FACTURATION],"<"&'CLIENTS-CREANCES'!$N$1) -> 0 | M13: =SUMIFS(Tableau6[NET A PAYER],Tableau6[CLIENT],Tableau1[[#This Row],[NOM CLIENT]],Tableau6[DATE DE FACTURATION],">="&'CLIENTS-CREANCES'!$N$1,Tableau6[DATE DE FACTURATION],"<="&'CLIENTS-CREANCES'!$O$1) -> 0 | N13: =SUMIFS(Tableau3[MONTANT TTC],Tableau3[CLIENTS],Tableau1[[#This Row],[NOM CLIENT]],Tableau3[[DATE DE PAIEMENT ]],">="&'CLIENTS-CREANCES'!$N$1,Tableau3[[DATE DE PAIEMENT ]],"<="&'CLIENTS-CREANCES'!$O$1) -> 0 | O13: =+SUMIFS(Tableau6[NET A PAYER],Tableau6[CLIENT],Tableau1[[#This Row],[NOM CLIENT]],Tableau6[DATE DE DEPOT],"<="&'CLIENTS-CREANCES'!$O$1)-SUMIFS(Tableau3[MONTANT TTC],Tableau3[CLIENTS],Tableau1[[#This Row],[NOM CLIENT]],Tableau3[[DATE DE PAIEMENT ]],"<="&'CLIENTS-CREANCES'!$O$1) -> 0
A14: KENAM S | B14: ETS. MSSZ | C14: ENTREPRISE | D14: 9410647 J | F14: 05 BP 1120 ABIDJAN 05 | H14: 27 22 42 73 48 | L14: =+SUMIFS(Tableau6[NET A PAYER],Tableau6[CLIENT],Tableau1[[#This Row],[NOM CLIENT]],Tableau6[DATE DE FACTURATION],"<"&'CLIENTS-CREANCES'!$N$1)-SUMIFS(Tableau6[MONTANT PAYE],Tableau6[CLIENT],Tableau1[[#This Row],[NOM CLIENT]],Tableau6[DATE DE FACTURATION],"<"&'CLIENTS-CREANCES'!$N$1) -> 0 | M14: =SUMIFS(Tableau6[NET A PAYER],Tableau6[CLIENT],Tableau1[[#This Row],[NOM CLIENT]],Tableau6[DATE DE FACTURATION],">="&'CLIENTS-CREANCES'!$N$1,Tableau6[DATE DE FACTURATION],"<="&'CLIENTS-CREANCES'!$O$1) -> 17369600 | N14: =SUMIFS(Tableau3[MONTANT TTC],Tableau3[CLIENTS],Tableau1[[#This Row],[NOM CLIENT]],Tableau3[[DATE DE PAIEMENT ]],">="&'CLIENTS-CREANCES'!$N$1,Tableau3[[DATE DE PAIEMENT ]],"<="&'CLIENTS-CREANCES'!$O$1) -> 0 | O14: =+SUMIFS(Tableau6[NET A PAYER],Tableau6[CLIENT],Tableau1[[#This Row],[NOM CLIENT]],Tableau6[DATE DE DEPOT],"<="&'CLIENTS-CREANCES'!$O$1)-SUMIFS(Tableau3[MONTANT TTC],Tableau3[CLIENTS],Tableau1[[#This Row],[NOM CLIENT]],Tableau3[[DATE DE PAIEMENT ]],"<="&'CLIENTS-CREANCES'!$O$1) -> 17369600
A15: KENAM S | B15: M BUER | C15: PARTICULIER | L15: =+SUMIFS(Tableau6[NET A PAYER],Tableau6[CLIENT],Tableau1[[#This Row],[NOM CLIENT]],Tableau6[DATE DE FACTURATION],"<"&'CLIENTS-CREANCES'!$N$1)-SUMIFS(Tableau6[MONTANT PAYE],Tableau6[CLIENT],Tableau1[[#This Row],[NOM CLIENT]],Tableau6[DATE DE FACTURATION],"<"&'CLIENTS-CREANCES'!$N$1) -> 0 | M15: =SUMIFS(Tableau6[NET A PAYER],Tableau6[CLIENT],Tableau1[[#This Row],[NOM CLIENT]],Tableau6[DATE DE FACTURATION],">="&'CLIENTS-CREANCES'!$N$1,Tableau6[DATE DE FACTURATION],"<="&'CLIENTS-CREANCES'!$O$1) -> 1645000 | N15: =SUMIFS(Tableau3[MONTANT TTC],Tableau3[CLIENTS],Tableau1[[#This Row],[NOM CLIENT]],Tableau3[[DATE DE PAIEMENT ]],">="&'CLIENTS-CREANCES'!$N$1,Tableau3[[DATE DE PAIEMENT ]],"<="&'CLIENTS-CREANCES'!$O$1) -> 1645000 | O15: =+SUMIFS(Tableau6[NET A PAYER],Tableau6[CLIENT],Tableau1[[#This Row],[NOM CLIENT]],Tableau6[DATE DE DEPOT],"<="&'CLIENTS-CREANCES'!$O$1)-SUMIFS(Tableau3[MONTANT TTC],Tableau3[CLIENTS],Tableau1[[#This Row],[NOM CLIENT]],Tableau3[[DATE DE PAIEMENT ]],"<="&'CLIENTS-CREANCES'!$O$1) -> 0
A16: KENAM S | B16: KHALIF INGENIERIE | C16: ENTREPRISE | F16: 23 BP 2992 ABIDJAN 23 | G16: YOPOUGON NOUVEAU QUARTIER | H16: 07 49 82 12 75 | I16: CONSTRUCTION METALLIQUE, BATIMENT TCE | L16: =+SUMIFS(Tableau6[NET A PAYER],Tableau6[CLIENT],Tableau1[[#This Row],[NOM CLIENT]],Tableau6[DATE DE FACTURATION],"<"&'CLIENTS-CREANCES'!$N$1)-SUMIFS(Tableau6[MONTANT PAYE],Tableau6[CLIENT],Tableau1[[#This Row],[NOM CLIENT]],Tableau6[DATE DE FACTURATION],"<"&'CLIENTS-CREANCES'!$N$1) -> 0 | M16: =SUMIFS(Tableau6[NET A PAYER],Tableau6[CLIENT],Tableau1[[#This Row],[NOM CLIENT]],Tableau6[DATE DE FACTURATION],">="&'CLIENTS-CREANCES'!$N$1,Tableau6[DATE DE FACTURATION],"<="&'CLIENTS-CREANCES'!$O$1) -> 0 | N16: =SUMIFS(Tableau3[MONTANT TTC],Tableau3[CLIENTS],Tableau1[[#This Row],[NOM CLIENT]],Tableau3[[DATE DE PAIEMENT ]],">="&'CLIENTS-CREANCES'!$N$1,Tableau3[[DATE DE PAIEMENT ]],"<="&'CLIENTS-CREANCES'!$O$1) -> 3540000 | O16: =+SUMIFS(Tableau6[NET A PAYER],Tableau6[CLIENT],Tableau1[[#This Row],[NOM CLIENT]],Tableau6[DATE DE DEPOT],"<="&'CLIENTS-CREANCES'!$O$1)-SUMIFS(Tableau3[MONTANT TTC],Tableau3[CLIENTS],Tableau1[[#This Row],[NOM CLIENT]],Tableau3[[DATE DE PAIEMENT ]],"<="&'CLIENTS-CREANCES'!$O$1) -> -3540000
A17: KENAM S | B17: KEDA CERAMIC | C17: ENTREPRISE | L17: =+SUMIFS(Tableau6[NET A PAYER],Tableau6[CLIENT],Tableau1[[#This Row],[NOM CLIENT]],Tableau6[DATE DE FACTURATION],"<"&'CLIENTS-CREANCES'!$N$1)-SUMIFS(Tableau6[MONTANT PAYE],Tableau6[CLIENT],Tableau1[[#This Row],[NOM CLIENT]],Tableau6[DATE DE FACTURATION],"<"&'CLIENTS-CREANCES'!$N$1) -> 0 | M17: =SUMIFS(Tableau6[NET A PAYER],Tableau6[CLIENT],Tableau1[[#This Row],[NOM CLIENT]],Tableau6[DATE DE FACTURATION],">="&'CLIENTS-CREANCES'!$N$1,Tableau6[DATE DE FACTURATION],"<="&'CLIENTS-CREANCES'!$O$1) -> 560000 | N17: =SUMIFS(Tableau3[MONTANT TTC],Tableau3[CLIENTS],Tableau1[[#This Row],[NOM CLIENT]],Tableau3[[DATE DE PAIEMENT ]],">="&'CLIENTS-CREANCES'!$N$1,Tableau3[[DATE DE PAIEMENT ]],"<="&'CLIENTS-CREANCES'!$O$1) -> 0 | O17: =+SUMIFS(Tableau6[NET A PAYER],Tableau6[CLIENT],Tableau1[[#This Row],[NOM CLIENT]],Tableau6[DATE DE DEPOT],"<="&'CLIENTS-CREANCES'!$O$1)-SUMIFS(Tableau3[MONTANT TTC],Tableau3[CLIENTS],Tableau1[[#This Row],[NOM CLIENT]],Tableau3[[DATE DE PAIEMENT ]],"<="&'CLIENTS-CREANCES'!$O$1) -> 0
L18: =+SUMIFS(Tableau6[NET A PAYER],Tableau6[CLIENT],Tableau1[[#This Row],[NOM CLIENT]],Tableau6[DATE DE FACTURATION],"<"&'CLIENTS-CREANCES'!$N$1)-SUMIFS(Tableau6[MONTANT PAYE],Tableau6[CLIENT],Tableau1[[#This Row],[NOM CLIENT]],Tableau6[DATE DE FACTURATION],"<"&'CLIENTS-CREANCES'!$N$1) -> 0 | M18: =SUMIFS(Tableau6[NET A PAYER],Tableau6[CLIENT],Tableau1[[#This Row],[NOM CLIENT]],Tableau6[DATE DE FACTURATION],">="&'CLIENTS-CREANCES'!$N$1,Tableau6[DATE DE FACTURATION],"<="&'CLIENTS-CREANCES'!$O$1) -> 0 | N18: =SUMIFS(Tableau3[MONTANT TTC],Tableau3[CLIENTS],Tableau1[[#This Row],[NOM CLIENT]],Tableau3[[DATE DE PAIEMENT ]],">="&'CLIENTS-CREANCES'!$N$1,Tableau3[[DATE DE PAIEMENT ]],"<="&'CLIENTS-CREANCES'!$O$1) -> 0 | O18: =+SUMIFS(Tableau6[NET A PAYER],Tableau6[CLIENT],Tableau1[[#This Row],[NOM CLIENT]],Tableau6[DATE DE DEPOT],"<="&'CLIENTS-CREANCES'!$O$1)-SUMIFS(Tableau3[MONTANT TTC],Tableau3[CLIENTS],Tableau1[[#This Row],[NOM CLIENT]],Tableau3[[DATE DE PAIEMENT ]],"<="&'CLIENTS-CREANCES'!$O$1) -> 0
L19: =+SUMIFS(Tableau6[NET A PAYER],Tableau6[CLIENT],Tableau1[[#This Row],[NOM CLIENT]],Tableau6[DATE DE FACTURATION],"<"&'CLIENTS-CREANCES'!$N$1)-SUMIFS(Tableau6[MONTANT PAYE],Tableau6[CLIENT],Tableau1[[#This Row],[NOM CLIENT]],Tableau6[DATE DE FACTURATION],"<"&'CLIENTS-CREANCES'!$N$1) -> 0 | M19: =SUMIFS(Tableau6[NET A PAYER],Tableau6[CLIENT],Tableau1[[#This Row],[NOM CLIENT]],Tableau6[DATE DE FACTURATION],">="&'CLIENTS-CREANCES'!$N$1,Tableau6[DATE DE FACTURATION],"<="&'CLIENTS-CREANCES'!$O$1) -> 0 | N19: =SUMIFS(Tableau3[MONTANT TTC],Tableau3[CLIENTS],Tableau1[[#This Row],[NOM CLIENT]],Tableau3[[DATE DE PAIEMENT ]],">="&'CLIENTS-CREANCES'!$N$1,Tableau3[[DATE DE PAIEMENT ]],"<="&'CLIENTS-CREANCES'!$O$1) -> 0 | O19: =+SUMIFS(Tableau6[NET A PAYER],Tableau6[CLIENT],Tableau1[[#This Row],[NOM CLIENT]],Tableau6[DATE DE DEPOT],"<="&'CLIENTS-CREANCES'!$O$1)-SUMIFS(Tableau3[MONTANT TTC],Tableau3[CLIENTS],Tableau1[[#This Row],[NOM CLIENT]],Tableau3[[DATE DE PAIEMENT ]],"<="&'CLIENTS-CREANCES'!$O$1) -> 0
L20: =+SUMIFS(Tableau6[NET A PAYER],Tableau6[CLIENT],Tableau1[[#This Row],[NOM CLIENT]],Tableau6[DATE DE FACTURATION],"<"&'CLIENTS-CREANCES'!$N$1)-SUMIFS(Tableau6[MONTANT PAYE],Tableau6[CLIENT],Tableau1[[#This Row],[NOM CLIENT]],Tableau6[DATE DE FACTURATION],"<"&'CLIENTS-CREANCES'!$N$1) -> 0 | M20: =SUMIFS(Tableau6[NET A PAYER],Tableau6[CLIENT],Tableau1[[#This Row],[NOM CLIENT]],Tableau6[DATE DE FACTURATION],">="&'CLIENTS-CREANCES'!$N$1,Tableau6[DATE DE FACTURATION],"<="&'CLIENTS-CREANCES'!$O$1) -> 0 | N20: =SUMIFS(Tableau3[MONTANT TTC],Tableau3[CLIENTS],Tableau1[[#This Row],[NOM CLIENT]],Tableau3[[DATE DE PAIEMENT ]],">="&'CLIENTS-CREANCES'!$N$1,Tableau3[[DATE DE PAIEMENT ]],"<="&'CLIENTS-CREANCES'!$O$1) -> 0 | O20: =+SUMIFS(Tableau6[NET A PAYER],Tableau6[CLIENT],Tableau1[[#This Row],[NOM CLIENT]],Tableau6[DATE DE DEPOT],"<="&'CLIENTS-CREANCES'!$O$1)-SUMIFS(Tableau3[MONTANT TTC],Tableau3[CLIENTS],Tableau1[[#This Row],[NOM CLIENT]],Tableau3[[DATE DE PAIEMENT ]],"<="&'CLIENTS-CREANCES'!$O$1) -> 0
A21: Total | B21: =SUBTOTAL(103,Tableau1[NOM CLIENT]) -> 13 | L21: =SUBTOTAL(109,Tableau1[SOLDE N-1]) -> 0 | M21: =SUBTOTAL(109,Tableau1[MONTANT DU]) -> 2589911320 | N21: =SUBTOTAL(109,Tableau1[MONTANT RECOUVRE]) -> 2.6975368e+09 | O21: =SUBTOTAL(109,Tableau1[SOLDE N]) -> -1.0818547e+08

Sheet FACTURES
B2: LISTES DES FACTURES
C3: Faire le tri
A4: ENTITE | B4: DATE DE FACTURATION | C4: DATE DE DEPOT | D4: NUM DE FACTURE | E4: CLIENT | F4: DESIGNATION | G4: PROJET/CHANTIER | H4: CODE TVA | I4: MONTANT HT BIEN | J4: MONTANT HT SERVICE | K4: MONTANT HT | L4: ACOMPTE SUR HT | M4: TVA | N4: MONTANT TTC | O4: ACOMPTE SUR TTC | P4: NET A PAYER | Q4: N° BC | R4: MONTANT BC HT | S4: DELAI | T4: DATE LIMITE | U4: JOURS DE RETARD | V4: STATUT | W4: MONTANT PAYE | X4: DATE PAIEMENT | Y4: SOLDE SUR FACTURE | Z4: OBSERVATIONS
A5: KENAM S | B5: 45665 | C5: 45665 | D5: 205 | E5: PFO CONSTRUCTION | F5: LOCATION DE CAMIONS | G5: 305R8002 | H5: TVAF | J5: 20234633 | K5: =+Tableau6[[#This Row],[MONTANT HT BIEN]]+Tableau6[[#This Row],[MONTANT HT SERVICE]] -> 20234633 | L5: 0 | M5: =+IFERROR(IF(Tableau6[[#This Row],[CODE TVA]]="TVAF",Tableau6[[#This Row],[MONTANT HT]]*0.18,0),0) -> 3642233.9 | N5: =Tableau6[[#This Row],[MONTANT HT]]+Tableau6[[#This Row],[TVA]]-Tableau6[[#This Row],[ACOMPTE SUR HT]] -> 23876867 | P5: =+ROUND(Tableau6[[#This Row],[MONTANT TTC]]-Tableau6[[#This Row],[ACOMPTE SUR TTC]],0) -> 23876867 | Q5: BC101017 | R5: =IFERROR(INDEX(Tableau2[[ID BC UNIQUE]:[MONTANT HT VALIDE]],MATCH(Tableau6[[#This Row],[N° BC]],Tableau2[ID BC UNIQUE],0),6),0) -> 20234633 | S5: =IFERROR(INDEX(Tableau2[[DATE]:[DELAIS DE PAIEMENT FACTURES EN JOUR]],MATCH(Tableau6[[#This Row],[N° BC]],Tableau2[ID BC UNIQUE],0),5),0) -> 30 | T5: =IF(ISBLANK(Tableau6[[#This Row],[DATE DE DEPOT]]),"",Tableau6[[#This Row],[DATE DE DEPOT]]+Tableau6[[#This Row],[DELAI]]) -> 45695 | U5: =+IF(AND(W5=0,Tableau6[[#This Row],[DATE LIMITE]]<TODAY()),TODAY()-Tableau6[[#This Row],[DATE LIMITE]],0) -> 0 | V5: =IF(Tableau6[[#This Row],[DATE LIMITE]]>=TODAY(),"NON ECHUE",IF(Tableau6[[#This Row],[MONTANT HT]]<0,IF(ISNUMBER(MATCH(-Tableau6[[#This Row],[MONTANT HT]],Tableau6[MONTANT HT],0)),"AVOIR TOTAL","AVOIR PARTIEL"),IF(AND(ISNUMBER(MATCH(-Tableau6[[#This Row],[MONTANT HT]],Tableau6[MONTANT HT],0)),(Tableau6[[#This Row],[ACOMPTE SUR TTC]]+Tableau6[[#This Row],[MONTANT PAYE]])=0),"FACTURE ANNULEE",IF(Tableau6[[#This Row],[ACOMPTE SUR TTC]]+Tableau6[[#This Row],[MONTANT PAYE]]=0,"ECHUE NON REGLEE",IF(Tableau6[[#This Row],[ACOMPTE SUR TTC]]+Tableau6[[#This Row],[MONTANT PAYE]]=Tableau6[[#This Row],[NET A PAYER]],"PAYE",IF(Tableau6[[#This Row],[ACOMPTE SUR TTC]]+Tableau6[[#This Row],[MONTANT PAYE]]<Tableau6[[#This Row],[NET A PAYER]],"PAIEMENT PARTIEL","TROP PAYE")))))) -> PAYE | W5: =SUMIF(Tableau3[FACTURE],Tableau6[[#This Row],[NUM DE FACTURE]],Tableau3[MONTANT TTC]) -> 23876867 | Y5: =+Tableau6[[#This Row],[NET A PAYER]]-Tableau6[[#This Row],[MONTANT PAYE]] -> 0
A6: KENAM S | B6: 45677 | C6: 45677 | D6: 208 | E6: PFO CONSTRUCTION | F6: LOCATION DE CAMIONS | G6: 348R8002 | H6: TVAF | J6: 3500000 | K6: =+Tableau6[[#This Row],[MONTANT HT BIEN]]+Tableau6[[#This Row],[MONTANT HT SERVICE]] -> 3500000 | L6: 0 | M6: =+IFERROR(IF(Tableau6[[#This Row],[CODE TVA]]="TVAF",Tableau6[[#This Row],[MONTANT HT]]*0.18,0),0) -> 630000 | N6: =Tableau6[[#This Row],[MONTANT HT]]+Tableau6[[#This Row],[TVA]]-Tableau6[[#This Row],[ACOMPTE SUR HT]] -> 4130000 | P6: =+ROUND(Tableau6[[#This Row],[MONTANT TTC]]-Tableau6[[#This Row],[ACOMPTE SUR TTC]],0) -> 4130000 | Q6: BC101167 | R6: =IFERROR(INDEX(Tableau2[[ID BC UNIQUE]:[MONTANT HT VALIDE]],MATCH(Tableau6[[#This Row],[N° BC]],Tableau2[ID BC UNIQUE],0),6),0) -> 3500000 | S6: =IFERROR(INDEX(Tableau2[[DATE]:[DELAIS DE PAIEMENT FACTURES EN JOUR]],MATCH(Tableau6[[#This Row],[N° BC]],Tableau2[ID BC UNIQUE],0),5),0) -> 30 | T6: =IF(ISBLANK(Tableau6[[#This Row],[DATE DE DEPOT]]),"",Tableau6[[#This Row],[DATE DE DEPOT]]+Tableau6[[#This Row],[DELAI]]) -> 45707 | U6: =+IF(AND(W6=0,Tableau6[[#This Row],[DATE LIMITE]]<TODAY()),TODAY()-Tableau6[[#This Row],[DATE LIMITE]],0) -> 0 | V6: =IF(Tableau6[[#This Row],[DATE LIMITE]]>=TODAY(),"NON ECHUE",IF(Tableau6[[#This Row],[MONTANT HT]]<0,IF(ISNUMBER(MATCH(-Tableau6[[#This Row],[MONTANT HT]],Tableau6[MONTANT HT],0)),"AVOIR TOTAL","AVOIR PARTIEL"),IF(AND(ISNUMBER(MATCH(-Tableau6[[#This Row],[MONTANT HT]],Tableau6[MONTANT HT],0)),(Tableau6[[#This Row],[ACOMPTE SUR TTC]]+Tableau6[[#This Row],[MONTANT PAYE]])=0),"FACTURE ANNULEE",IF(Tableau6[[#This Row],[ACOMPTE SUR TTC]]+Tableau6[[#This Row],[MONTANT PAYE]]=0,"ECHUE NON REGLEE",IF(Tableau6[[#This Row],[ACOMPTE SUR TTC]]+Tableau6[[#This Row],[MONTANT PAYE]]=Tableau6[[#This Row],[NET A PAYER]],"PAYE",IF(Tableau6[[#This Row],[ACOMPTE SUR TTC]]+Tableau6[[#This Row],[MONTANT PAYE]]<Tableau6[[#This Row],[NET A PAYER]],"PAIEMENT PARTIEL","TROP PAYE")))))) -> PAYE | W6: =SUMIF(Tableau3[FACTURE],Tableau6[[#This Row],[NUM DE FACTURE]],Tableau3[MONTANT TTC]) -> 4130000 | Y6: =+Tableau6[[#This Row],[NET A PAYER]]-Tableau6[[#This Row],[MONTANT PAYE]] -> 0
A7: KENAM S | B7: 45677 | C7: 45677 | D7: 209 | E7: PFO CONSTRUCTION | F7: LOCATION DE CAMIONS | G7: 348R8002 | H7: TVAF | J7: 720000 | K7: =+Tableau6[[#This Row],[MONTANT HT BIEN]]+Tableau6[[#This Row],[MONTANT HT SERVICE]] -> 720000 | L7: 0 | M7: =+IFERROR(IF(Tableau6[[#This Row],[CODE TVA]]="TVAF",Tableau6[[#This Row],[MONTANT HT]]*0.18,0),0) -> 129600 | N7: =Tableau6[[#This Row],[MONTANT HT]]+Tableau6[[#This Row],[TVA]]-Tableau6[[#This Row],[ACOMPTE SUR HT]] -> 849600 | P7: =+ROUND(Tableau6[[#This Row],[MONTANT TTC]]-Tableau6[[#This Row],[ACOMPTE SUR TTC]],0) -> 849600 | Q7: BC101169 | R7: =IFERROR(INDEX(Tableau2[[ID BC UNIQUE]:[MONTANT HT VALIDE]],MATCH(Tableau6[[#This Row],[N° BC]],Tableau2[ID BC UNIQUE],0),6),0) -> 720000 | S7: =IFERROR(INDEX(Tableau2[[DATE]:[DELAIS DE PAIEMENT FACTURES EN JOUR]],MATCH(Tableau6[[#This Row],[N° BC]],Tableau2[ID BC UNIQUE],0),5),0) -> 30 | T7: =IF(ISBLANK(Tableau6[[#This Row],[DATE DE DEPOT]]),"",Tableau6[[#This Row],[DATE DE DEPOT]]+Tableau6[[#This Row],[DELAI]]) -> 45707 | U7: =+IF(AND(W7=0,Tableau6[[#This Row],[DATE LIMITE]]<TODAY()),TODAY()-Tableau6[[#This Row],[DATE LIMITE]],0) -> 0 | V7: =IF(Tableau6[[#This Row],[DATE LIMITE]]>=TODAY(),"NON ECHUE",IF(Tableau6[[#This Row],[MONTANT HT]]<0,IF(ISNUMBER(MATCH(-Tableau6[[#This Row],[MONTANT HT]],Tableau6[MONTANT HT],0)),"AVOIR TOTAL","AVOIR PARTIEL"),IF(AND(ISNUMBER(MATCH(-Tableau6[[#This Row],[MONTANT HT]],Tableau6[MONTANT HT],0)),(Tableau6[[#This Row],[ACOMPTE SUR TTC]]+Tableau6[[#This Row],[MONTANT PAYE]])=0),"FACTURE ANNULEE",IF(Tableau6[[#This Row],[ACOMPTE SUR TTC]]+Tableau6[[#This Row],[MONTANT PAYE]]=0,"ECHUE NON REGLEE",IF(Tableau6[[#This Row],[ACOMPTE SUR TTC]]+Tableau6[[#This Row],[MONTANT PAYE]]=Tableau6[[#This Row],[NET A PAYER]],"PAYE",IF(Tableau6[[#This Row],[ACOMPTE SUR TTC]]+Tableau6[[#This Row],[MONTANT PAYE]]<Tableau6[[#This Row],[NET A PAYER]],"PAIEMENT PARTIEL","TROP PAYE")))))) -> PAYE | W7: =SUMIF(Tableau3[FACTURE],Tableau6[[#This Row],[NUM DE FACTURE]],Tableau3[MONTANT TTC]) -> 849600 | Y7: =+Tableau6[[#This Row],[NET A PAYER]]-Tableau6[[#This Row],[MONTANT PAYE]] -> 0
A8: KENAM S | B8: 45679 | C8: 45679 | D8: 210 | E8: PFO CONSTRUCTION | F8: VENTE DE MATERIEL | G8: 252B0209 | H8: TVAF | I8: 6064800 | K8: =+Tableau6[[#This Row],[MONTANT HT BIEN]]+Tableau6[[#This Row],[MONTANT HT SERVICE]] -> 6064800 | L8: 0 | M8: =+IFERROR(IF(Tableau6[[#This Row],[CODE TVA]]="TVAF",Tableau6[[#This Row],[MONTANT HT]]*0.18,0),0) -> 1091664 | N8: =Tableau6[[#This Row],[MONTANT HT]]+Tableau6[[#This Row],[TVA]]-Tableau6[[#This Row],[ACOMPTE SUR HT]] -> 7156464 | P8: =+ROUND(Tableau6[[#This Row],[MONTANT TTC]]-Tableau6[[#This Row],[ACOMPTE SUR TTC]],0) -> 7156464 | Q8: BC200691 | R8: =IFERROR(INDEX(Tableau2[[ID BC UNIQUE]:[MONTANT HT VALIDE]],MATCH(Tableau6[[#This Row],[N° BC]],Tableau2[ID BC UNIQUE],0),6),0) -> 6064800 | S8: =IFERROR(INDEX(Tableau2[[DATE]:[DELAIS DE PAIEMENT FACTURES EN JOUR]],MATCH(Tableau6[[#This Row],[N° BC]],Tableau2[ID BC UNIQUE],0),5),0) -> 30 | T8: =IF(ISBLANK(Tableau6[[#This Row],[DATE DE DEPOT]]),"",Tableau6[[#This Row],[DATE DE DEPOT]]+Tableau6[[#This Row],[DELAI]]) -> 45709 | U8: =+IF(AND(W8=0,Tableau6[[#This Row],[DATE LIMITE]]<TODAY()),TODAY()-Tableau6[[#This Row],[DATE LIMITE]],0) -> 0 | V8: =IF(Tableau6[[#This Row],[DATE LIMITE]]>=TODAY(),"NON ECHUE",IF(Tableau6[[#This Row],[MONTANT HT]]<0,IF(ISNUMBER(MATCH(-Tableau6[[#This Row],[MONTANT HT]],Tableau6[MONTANT HT],0)),"AVOIR TOTAL","AVOIR PARTIEL"),IF(AND(ISNUMBER(MATCH(-Tableau6[[#This Row],[MONTANT HT]],Tableau6[MONTANT HT],0)),(Tableau6[[#This Row],[ACOMPTE SUR TTC]]+Tableau6[[#This Row],[MONTANT PAYE]])=0),"FACTURE ANNULEE",IF(Tableau6[[#This Row],[ACOMPTE SUR TTC]]+Tableau6[[#This Row],[MONTANT PAYE]]=0,"ECHUE NON REGLEE",IF(Tableau6[[#This Row],[ACOMPTE SUR TTC]]+Tableau6[[#This Row],[MONTANT PAYE]]=Tableau6[[#This Row],[NET A PAYER]],"PAYE",IF(Tableau6[[#This Row],[ACOMPTE SUR TTC]]+Tableau6[[#This Row],[MONTANT PAYE]]<Tableau6[[#This Row],[NET A PAYER]],"PAIEMENT PARTIEL","TROP PAYE")))))) -> PAYE | W8: =SUMIF(Tableau3[FACTURE],Tableau6[[#This Row],[NUM DE FACTURE]],Tableau3[MONTANT TTC]) -> 7156464 | Y8: =+Tableau6[[#This Row],[NET A PAYER]]-Tableau6[[#This Row],[MONTANT PAYE]] -> 0
A9: KENAM S | B9: 45680 | C9: 45680 | D9: 212 | E9: PFO CONSTRUCTION | F9: LOCATION DE CAMIONS | G9: 257B0209 | H9: TVAF | J9: 540000 | K9: =+Tableau6[[#This Row],[MONTANT HT BIEN]]+Tableau6[[#This Row],[MONTANT HT SERVICE]] -> 540000 | L9: 0 | M9: =+IFERROR(IF(Tableau6[[#This Row],[CODE TVA]]="TVAF",Tableau6[[#This Row],[MONTANT HT]]*0.18,0),0) -> 97200 | N9: =Tableau6[[#This Row],[MONTANT HT]]+Tableau6[[#This Row],[TVA]]-Tableau6[[#This Row],[ACOMPTE SUR HT]] -> 637200 | P9: =+ROUND(Tableau6[[#This Row],[MONTANT TTC]]-Tableau6[[#This Row],[ACOMPTE SUR TTC]],0) -> 637200 | Q9: BC200850 | R9: =IFERROR(INDEX(Tableau2[[ID BC UNIQUE]:[MONTANT HT VALIDE]],MATCH(Tableau6[[#This Row],[N° BC]],Tableau2[ID BC UNIQUE],0),6),0) -> 540000 | S9: =IFERROR(INDEX(Tableau2[[DATE]:[DELAIS DE PAIEMENT FACTURES EN JOUR]],MATCH(Tableau6[[#This Row],[N° BC]],Tableau2[ID BC UNIQUE],0),5),0) -> 30 | T9: =IF(ISBLANK(Tableau6[[#This Row],[DATE DE DEPOT]]),"",Tableau6[[#This Row],[DATE DE DEPOT]]+Tableau6[[#This Row],[DELAI]]) -> 45710 | U9: =+IF(AND(W9=0,Tableau6[[#This Row],[DATE LIMITE]]<TODAY()),TODAY()-Tableau6[[#This Row],[DATE LIMITE]],0) -> 0 | V9: =IF(Tableau6[[#This Row],[DATE LIMITE]]>=TODAY(),"NON ECHUE",IF(Tableau6[[#This Row],[MONTANT HT]]<0,IF(ISNUMBER(MATCH(-Tableau6[[#This Row],[MONTANT HT]],Tableau6[MONTANT HT],0)),"AVOIR TOTAL","AVOIR PARTIEL"),IF(AND(ISNUMBER(MATCH(-Tableau6[[#This Row],[MONTANT HT]],Tableau6[MONTANT HT],0)),(Tableau6[[#This Row],[ACOMPTE SUR TTC]]+Tableau6[[#This Row],[MONTANT PAYE]])=0),"FACTURE ANNULEE",IF(Tableau6[[#This Row],[ACOMPTE SUR TTC]]+Tableau6[[#This Row],[MONTANT PAYE]]=0,"ECHUE NON REGLEE",IF(Tableau6[[#This Row],[ACOMPTE SUR TTC]]+Tableau6[[#This Row],[MONTANT PAYE]]=Tableau6[[#This Row],[NET A PAYER]],"PAYE",IF(Tableau6[[#This Row],[ACOMPTE SUR TTC]]+Tableau6[[#This Row],[MONTANT PAYE]]<Tableau6[[#This Row],[NET A PAYER]],"PAIEMENT PARTIEL","TROP PAYE")))))) -> PAYE | W9: =SUMIF(Tableau3[FACTURE],Tableau6[[#This Row],[NUM DE FACTURE]],Tableau3[MONTANT TTC]) -> 637200 | Y9: =+Tableau6[[#This Row],[NET A PAYER]]-Tableau6[[#This Row],[MONTANT PAYE]] -> 0
A10: KENAM S | B10: 45680 | C10: 45680 | D10: 213 | E10: PFO CONSTRUCTION | F10: LOCATION DE CAMIONS | G10: 257B0207 | H10: TVAF | J10: 1980000 | K10: =+Tableau6[[#This Row],[MONTANT HT BIEN]]+Tableau6[[#This Row],[MONTANT HT SERVICE]] -> 1980000 | L10: 0 | M10: =+IFERROR(IF(Tableau6[[#This Row],[CODE TVA]]="TVAF",Tableau6[[#This Row],[MONTANT HT]]*0.18,0),0) -> 356400 | N10: =Tableau6[[#This Row],[MONTANT HT]]+Tableau6[[#This Row],[TVA]]-Tableau6[[#This Row],[ACOMPTE SUR HT]] -> 2336400 | P10: =+ROUND(Tableau6[[#This Row],[MONTANT TTC]]-Tableau6[[#This Row],[ACOMPTE SUR TTC]],0) -> 2336400 | Q10: BC200851 | R10: =IFERROR(INDEX(Tableau2[[ID BC UNIQUE]:[MONTANT HT VALIDE]],MATCH(Tableau6[[#This Row],[N° BC]],Tableau2[ID BC UNIQUE],0),6),0) -> 1980000 | S10: =IFERROR(INDEX(Tableau2[[DATE]:[DELAIS DE PAIEMENT FACTURES EN JOUR]],MATCH(Tableau6[[#This Row],[N° BC]],Tableau2[ID BC UNIQUE],0),5),0) -> 30 | T10: =IF(ISBLANK(Tableau6[[#This Row],[DATE DE DEPOT]]),"",Tableau6[[#This Row],[DATE DE DEPOT]]+Tableau6[[#This Row],[DELAI]]) -> 45710 | U10: =+IF(AND(W10=0,Tableau6[[#This Row],[DATE LIMITE]]<TODAY()),TODAY()-Tableau6[[#This Row],[DATE LIMITE]],0) -> 0 | V10: =IF(Tableau6[[#This Row],[DATE LIMITE]]>=TODAY(),"NON ECHUE",IF(Tableau6[[#This Row],[MONTANT HT]]<0,IF(ISNUMBER(MATCH(-Tableau6[[#This Row],[MONTANT HT]],Tableau6[MONTANT HT],0)),"AVOIR TOTAL","AVOIR PARTIEL"),IF(AND(ISNUMBER(MATCH(-Tableau6[[#This Row],[MONTANT HT]],Tableau6[MONTANT HT],0)),(Tableau6[[#This Row],[ACOMPTE SUR TTC]]+Tableau6[[#This Row],[MONTANT PAYE]])=0),"FACTURE ANNULEE",IF(Tableau6[[#This Row],[ACOMPTE SUR TTC]]+Tableau6[[#This Row],[MONTANT PAYE]]=0,"ECHUE NON REGLEE",IF(Tableau6[[#This Row],[ACOMPTE SUR TTC]]+Tableau6[[#This Row],[MONTANT PAYE]]=Tableau6[[#This Row],[NET A PAYER]],"PAYE",IF(Tableau6[[#This Row],[ACOMPTE SUR TTC]]+Tableau6[[#This Row],[MONTANT PAYE]]<Tableau6[[#This Row],[NET A PAYER]],"PAIEMENT PARTIEL","TROP PAYE")))))) -> PAYE | W10: =SUMIF(Tableau3[FACTURE],Tableau6[[#This Row],[NUM DE FACTURE]],Tableau3[MONTANT TTC]) -> 2336400 | Y10: =+Tableau6[[#This Row],[NET A PAYER]]-Tableau6[[#This Row],[MONTANT PAYE]] -> 0
A11: KENAM S | B11: 45680 | C11: 45680 | D11: 214 | E11: PFO CONSTRUCTION | F11: LOCATION DE CAMIONS | G11: 257B0207 | H11: TVAF | J11: 2200000 | K11: =+Tableau6[[#This Row],[MONTANT HT BIEN]]+Tableau6[[#This Row],[MONTANT HT SERVICE]] -> 2200000 | L11: 0 | M11: =+IFERROR(IF(Tableau6[[#This Row],[CODE TVA]]="TVAF",Tableau6[[#This Row],[MONTANT HT]]*0.18,0),0) -> 396000 | N11: =Tableau6[[#This Row],[MONTANT HT]]+Tableau6[[#This Row],[TVA]]-Tableau6[[#This Row],[ACOMPTE SUR HT]] -> 2596000 | P11: =+ROUND(Tableau6[[#This Row],[MONTANT TTC]]-Tableau6[[#This Row],[ACOMPTE SUR TTC]],0) -> 2596000 | Q11: BC200852 | R11: =IFERROR(INDEX(Tableau2[[ID BC UNIQUE]:[MONTANT HT VALIDE]],MATCH(Tableau6[[#This Row],[N° BC]],Tableau2[ID BC UNIQUE],0),6),0) -> 2200000 | S11: =IFERROR(INDEX(Tableau2[[DATE]:[DELAIS DE PAIEMENT FACTURES EN JOUR]],MATCH(Tableau6[[#This Row],[N° BC]],Tableau2[ID BC UNIQUE],0),5),0) -> 30 | T11: =IF(ISBLANK(Tableau6[[#This Row],[DATE DE DEPOT]]),"",Tableau6[[#This Row],[DATE DE DEPOT]]+Tableau6[[#This Row],[DELAI]]) -> 45710 | U11: =+IF(AND(W11=0,Tableau6[[#This Row],[DATE LIMITE]]<TODAY()),TODAY()-Tableau6[[#This Row],[DATE LIMITE]],0) -> 0 | V11: =IF(Tableau6[[#This Row],[DATE LIMITE]]>=TODAY(),"NON ECHUE",IF(Tableau6[[#This Row],[MONTANT HT]]<0,IF(ISNUMBER(MATCH(-Tableau6[[#This Row],[MONTANT HT]],Tableau6[MONTANT HT],0)),"AVOIR TOTAL","AVOIR PARTIEL"),IF(AND(ISNUMBER(MATCH(-Tableau6[[#This Row],[MONTANT HT]],Tableau6[MONTANT HT],0)),(Tableau6[[#This Row],[ACOMPTE SUR TTC]]+Tableau6[[#This Row],[MONTANT PAYE]])=0),"FACTURE ANNULEE",IF(Tableau6[[#This Row],[ACOMPTE SUR TTC]]+Tableau6[[#This Row],[MONTANT PAYE]]=0,"ECHUE NON REGLEE",IF(Tableau6[[#This Row],[ACOMPTE SUR TTC]]+Tableau6[[#This Row],[MONTANT PAYE]]=Tableau6[[#This Row],[NET A PAYER]],"PAYE",IF(Tableau6[[#This Row],[ACOMPTE SUR TTC]]+Tableau6[[#This Row],[MONTANT PAYE]]<Tableau6[[#This Row],[NET A PAYER]],"PAIEMENT PARTIEL","TROP PAYE")))))) -> PAYE | W11: =SUMIF(Tableau3[FACTURE],Tableau6[[#This Row],[NUM DE FACTURE]],Tableau3[MONTANT TTC]) -> 2596000 | Y11: =+Tableau6[[#This Row],[NET A PAYER]]-Tableau6[[#This Row],[MONTANT PAYE]] -> 0
A12: KENAM S | B12: 45680 | C12: 45680 | D12: 215 | E12: PFO CONSTRUCTION | F12: LOCATION DE CAMIONS | G12: 257B0209 | H12: TVAF | J12: 1400000 | K12: =+Tableau6[[#This Row],[MONTANT HT BIEN]]+Tableau6[[#This Row],[MONTANT HT SERVICE]] -> 1400000 | L12: 0 | M12: =+IFERROR(IF(Tableau6[[#This Row],[CODE TVA]]="TVAF",Tableau6[[#This Row],[MONTANT HT]]*0.18,0),0) -> 252000 | N12: =Tableau6[[#This Row],[MONTANT HT]]+Tableau6[[#This Row],[TVA]]-Tableau6[[#This Row],[ACOMPTE SUR HT]] -> 1652000 | P12: =+ROUND(Tableau6[[#This Row],[MONTANT TTC]]-Tableau6[[#This Row],[ACOMPTE SUR TTC]],0) -> 1652000 | Q12: BC200853 | R12: =IFERROR(INDEX(Tableau2[[ID BC UNIQUE]:[MONTANT HT VALIDE]],MATCH(Tableau6[[#This Row],[N° BC]],Tableau2[ID BC UNIQUE],0),6),0) -> 1400000 | S12: =IFERROR(INDEX(Tableau2[[DATE]:[DELAIS DE PAIEMENT FACTURES EN JOUR]],MATCH(Tableau6[[#This Row],[N° BC]],Tableau2[ID BC UNIQUE],0),5),0) -> 30 | T12: =IF(ISBLANK(Tableau6[[#This Row],[DATE DE DEPOT]]),"",Tableau6[[#This Row],[DATE DE DEPOT]]+Tableau6[[#This Row],[DELAI]]) -> 45710 | U12: =+IF(AND(W12=0,Tableau6[[#This Row],[DATE LIMITE]]<TODAY()),TODAY()-Tableau6[[#This Row],[DATE LIMITE]],0) -> 0 | V12: =IF(Tableau6[[#This Row],[DATE LIMITE]]>=TODAY(),"NON ECHUE",IF(Tableau6[[#This Row],[MONTANT HT]]<0,IF(ISNUMBER(MATCH(-Tableau6[[#This Row],[MONTANT HT]],Tableau6[MONTANT HT],0)),"AVOIR TOTAL","AVOIR PARTIEL"),IF(AND(ISNUMBER(MATCH(-Tableau6[[#This Row],[MONTANT HT]],Tableau6[MONTANT HT],0)),(Tableau6[[#This Row],[ACOMPTE SUR TTC]]+Tableau6[[#This Row],[MONTANT PAYE]])=0),"FACTURE ANNULEE",IF(Tableau6[[#This Row],[ACOMPTE SUR TTC]]+Tableau6[[#This Row],[MONTANT PAYE]]=0,"ECHUE NON REGLEE",IF(Tableau6[[#This Row],[ACOMPTE SUR TTC]]+Tableau6[[#This Row],[MONTANT PAYE]]=Tableau6[[#This Row],[NET A PAYER]],"PAYE",IF(Tableau6[[#This Row],[ACOMPTE SUR TTC]]+Tableau6[[#This Row],[MONTANT PAYE]]<Tableau6[[#This Row],[NET A PAYER]],"PAIEMENT PARTIEL","TROP PAYE")))))) -> PAYE | W12: =SUMIF(Tableau3[FACTURE],Tableau6[[#This Row],[NUM DE FACTURE]],Tableau3[MONTANT TTC]) -> 1652000 | Y12: =+Tableau6[[#This Row],[NET A PAYER]]-Tableau6[[#This Row],[MONTANT PAYE]] -> 0
A13: KENAM S | B13: 45680 | C13: 45680 | D13: 216 | E13: PFO CONSTRUCTION | F13: LOCATION DE CAMIONS | G13: 257B0209 | H13: TVAF | J13: 1350000 | K13: =+Tableau6[[#This Row],[MONTANT HT BIEN]]+Tableau6[[#This Row],[MONTANT HT SERVICE]] -> 1350000 | L13: 0 | M13: =+IFERROR(IF(Tableau6[[#This Row],[CODE TVA]]="TVAF",Tableau6[[#This Row],[MONTANT HT]]*0.18,0),0) -> 243000 | N13: =Tableau6[[#This Row],[MONTANT HT]]+Tableau6[[#This Row],[TVA]]-Tableau6[[#This Row],[ACOMPTE SUR HT]] -> 1593000 | P13: =+ROUND(Tableau6[[#This Row],[MONTANT TTC]]-Tableau6[[#This Row],[ACOMPTE SUR TTC]],0) -> 1593000 | Q13: BC200854 | R13: =IFERROR(INDEX(Tableau2[[ID BC UNIQUE]:[MONTANT HT VALIDE]],MATCH(Tableau6[[#This Row],[N° BC]],Tableau2[ID BC UNIQUE],0),6),0) -> 1350000 | S13: =IFERROR(INDEX(Tableau2[[DATE]:[DELAIS DE PAIEMENT FACTURES EN JOUR]],MATCH(Tableau6[[#This Row],[N° BC]],Tableau2[ID BC UNIQUE],0),5),0) -> 30 | T13: =IF(ISBLANK(Tableau6[[#This Row],[DATE DE DEPOT]]),"",Tableau6[[#This Row],[DATE DE DEPOT]]+Tableau6[[#This Row],[DELAI]]) -> 45710 | U13: =+IF(AND(W13=0,Tableau6[[#This Row],[DATE LIMITE]]<TODAY()),TODAY()-Tableau6[[#This Row],[DATE LIMITE]],0) -> 0 | V13: =IF(Tableau6[[#This Row],[DATE LIMITE]]>=TODAY(),"NON ECHUE",IF(Tableau6[[#This Row],[MONTANT HT]]<0,IF(ISNUMBER(MATCH(-Tableau6[[#This Row],[MONTANT HT]],Tableau6[MONTANT HT],0)),"AVOIR TOTAL","AVOIR PARTIEL"),IF(AND(ISNUMBER(MATCH(-Tableau6[[#This Row],[MONTANT HT]],Tableau6[MONTANT HT],0)),(Tableau6[[#This Row],[ACOMPTE SUR TTC]]+Tableau6[[#This Row],[MONTANT PAYE]])=0),"FACTURE ANNULEE",IF(Tableau6[[#This Row],[ACOMPTE SUR TTC]]+Tableau6[[#This Row],[MONTANT PAYE]]=0,"ECHUE NON REGLEE",IF(Tableau6[[#This Row],[ACOMPTE SUR TTC]]+Tableau6[[#This Row],[MONTANT PAYE]]=Tableau6[[#This Row],[NET A PAYER]],"PAYE",IF(Tableau6[[#This Row],[ACOMPTE SUR TTC]]+Tableau6[[#This Row],[MONTANT PAYE]]<Tableau6[[#This Row],[NET A PAYER]],"PAIEMENT PARTIEL","TROP PAYE")))))) -> PAYE | W13: =SUMIF(Tableau3[FACTURE],Tableau6[[#This Row],[NUM DE FACTURE]],Tableau3[MONTANT TTC]) -> 1593000 | Y13: =+Tableau6[[#This Row],[NET A PAYER]]-Tableau6[[#This Row],[MONTANT PAYE]] -> 0
A14: KENAM S | B14: 45680 | C14: 45680 | D14: 217 | E14: PFO CONSTRUCTION | F14: LOCATION DE CAMIONS | G14: 257B0200 | H14: TVAF | J14: 3500000 | K14: =+Tableau6[[#This Row],[MONTANT HT BIEN]]+Tableau6[[#This Row],[MONTANT HT SERVICE]] -> 3500000 | L14: 0 | M14: =+IFERROR(IF(Tableau6[[#This Row],[CODE TVA]]="TVAF",Tableau6[[#This Row],[MONTANT HT]]*0.18,0),0) -> 630000 | N14: =Tableau6[[#This Row],[MONTANT HT]]+Tableau6[[#This Row],[TVA]]-Tableau6[[#This Row],[ACOMPTE SUR HT]] -> 4130000 | P14: =+ROUND(Tableau6[[#This Row],[MONTANT TTC]]-Tableau6[[#This Row],[ACOMPTE SUR TTC]],0) -> 4130000 | Q14: BC200855 | R14: =IFERROR(INDEX(Tableau2[[ID BC UNIQUE]:[MONTANT HT VALIDE]],MATCH(Tableau6[[#This Row],[N° BC]],Tableau2[ID BC UNIQUE],0),6),0) -> 3500000 | S14: =IFERROR(INDEX(Tableau2[[DATE]:[DELAIS DE PAIEMENT FACTURES EN JOUR]],MATCH(Tableau6[[#This Row],[N° BC]],Tableau2[ID BC UNIQUE],0),5),0) -> 30 | T14: =IF(ISBLANK(Tableau6[[#This Row],[DATE DE DEPOT]]),"",Tableau6[[#This Row],[DATE DE DEPOT]]+Tableau6[[#This Row],[DELAI]]) -> 45710 | U14: =+IF(AND(W14=0,Tableau6[[#This Row],[DATE LIMITE]]<TODAY()),TODAY()-Tableau6[[#This Row],[DATE LIMITE]],0) -> 0 | V14: =IF(Tableau6[[#This Row],[DATE LIMITE]]>=TODAY(),"NON ECHUE",IF(Tableau6[[#This Row],[MONTANT HT]]<0,IF(ISNUMBER(MATCH(-Tableau6[[#This Row],[MONTANT HT]],Tableau6[MONTANT HT],0)),"AVOIR TOTAL","AVOIR PARTIEL"),IF(AND(ISNUMBER(MATCH(-Tableau6[[#This Row],[MONTANT HT]],Tableau6[MONTANT HT],0)),(Tableau6[[#This Row],[ACOMPTE SUR TTC]]+Tableau6[[#This Row],[MONTANT PAYE]])=0),"FACTURE ANNULEE",IF(Tableau6[[#This Row],[ACOMPTE SUR TTC]]+Tableau6[[#This Row],[MONTANT PAYE]]=0,"ECHUE NON REGLEE",IF(Tableau6[[#This Row],[ACOMPTE SUR TTC]]+Tableau6[[#This Row],[MONTANT PAYE]]=Tableau6[[#This Row],[NET A PAYER]],"PAYE",IF(Tableau6[[#This Row],[ACOMPTE SUR TTC]]+Tableau6[[#This Row],[MONTANT PAYE]]<Tableau6[[#This Row],[NET A PAYER]],"PAIEMENT PARTIEL","TROP PAYE")))))) -> PAYE | W14: =SUMIF(Tableau3[FACTURE],Tableau6[[#This Row],[NUM DE FACTURE]],Tableau3[MONTANT TTC]) -> 4130000 | Y14: =+Tableau6[[#This Row],[NET A PAYER]]-Tableau6[[#This Row],[MONTANT PAYE]] -> 0
A15: KENAM S | B15: 45680 | C15: 45680 | D15: 218 | E15: PFO CONSTRUCTION | F15: LOCATION DE CAMIONS | G15: 257B0203 | H15: TVAF | J15: 540000 | K15: =+Tableau6[[#This Row],[MONTANT HT BIEN]]+Tableau6[[#This Row],[MONTANT HT SERVICE]] -> 540000 | L15: 0 | M15: =+IFERROR(IF(Tableau6[[#This Row],[CODE TVA]]="TVAF",Tableau6[[#This Row],[MONTANT HT]]*0.18,0),0) -> 97200 | N15: =Tableau6[[#This Row],[MONTANT HT]]+Tableau6[[#This Row],[TVA]]-Tableau6[[#This Row],[ACOMPTE SUR HT]] -> 637200 | P15: =+ROUND(Tableau6[[#This Row],[MONTANT TTC]]-Tableau6[[#This Row],[ACOMPTE SUR TTC]],0) -> 637200 | Q15: BC200856 | R15: =IFERROR(INDEX(Tableau2[[ID BC UNIQUE]:[MONTANT HT VALIDE]],MATCH(Tableau6[[#This Row],[N° BC]],Tableau2[ID BC UNIQUE],0),6),0) -> 540000 | S15: =IFERROR(INDEX(Tableau2[[DATE]:[DELAIS DE PAIEMENT FACTURES EN JOUR]],MATCH(Tableau6[[#This Row],[N° BC]],Tableau2[ID BC UNIQUE],0),5),0) -> 30 | T15: =IF(ISBLANK(Tableau6[[#This Row],[DATE DE DEPOT]]),"",Tableau6[[#This Row],[DATE DE DEPOT]]+Tableau6[[#This Row],[DELAI]]) -> 45710 | U15: =+IF(AND(W15=0,Tableau6[[#This Row],[DATE LIMITE]]<TODAY()),TODAY()-Tableau6[[#This Row],[DATE LIMITE]],0) -> 0 | V15: =IF(Tableau6[[#This Row],[DATE LIMITE]]>=TODAY(),"NON ECHUE",IF(Tableau6[[#This Row],[MONTANT HT]]<0,IF(ISNUMBER(MATCH(-Tableau6[[#This Row],[MONTANT HT]],Tableau6[MONTANT HT],0)),"AVOIR TOTAL","AVOIR PARTIEL"),IF(AND(ISNUMBER(MATCH(-Tableau6[[#This Row],[MONTANT HT]],Tableau6[MONTANT HT],0)),(Tableau6[[#This Row],[ACOMPTE SUR TTC]]+Tableau6[[#This Row],[MONTANT PAYE]])=0),"FACTURE ANNULEE",IF(Tableau6[[#This Row],[ACOMPTE SUR TTC]]+Tableau6[[#This Row],[MONTANT PAYE]]=0,"ECHUE NON REGLEE",IF(Tableau6[[#This Row],[ACOMPTE SUR TTC]]+Tableau6[[#This Row],[MONTANT PAYE]]=Tableau6[[#This Row],[NET A PAYER]],"PAYE",IF(Tableau6[[#This Row],[ACOMPTE SUR TTC]]+Tableau6[[#This Row],[MONTANT PAYE]]<Tableau6[[#This Row],[NET A PAYER]],"PAIEMENT PARTIEL","TROP PAYE")))))) -> PAYE | W15: =SUMIF(Tableau3[FACTURE],Tableau6[[#This Row],[NUM DE FACTURE]],Tableau3[MONTANT TTC]) -> 637200 | Y15: =+Tableau6[[#This Row],[NET A PAYER]]-Tableau6[[#This Row],[MONTANT PAYE]] -> 0
A16: KENAM S | B16: 45680 | C16: 45680 | D16: 219 | E16: PFO CONSTRUCTION | F16: LOCATION DE CAMIONS | G16: 257B0209 | H16: TVAF | J16: 4000000 | K16: =+Tableau6[[#This Row],[MONTANT HT BIEN]]+Tableau6[[#This Row],[MONTANT HT SERVICE]] -> 4000000 | L16: 0 | M16: =+IFERROR(IF(Tableau6[[#This Row],[CODE TVA]]="TVAF",Tableau6[[#This Row],[MONTANT HT]]*0.18,0),0) -> 720000 | N16: =Tableau6[[#This Row],[MONTANT HT]]+Tableau6[[#This Row],[TVA]]-Tableau6[[#This Row],[ACOMPTE SUR HT]] -> 4720000 | P16: =+ROUND(Tableau6[[#This Row],[MONTANT TTC]]-Tableau6[[#This Row],[ACOMPTE SUR TTC]],0) -> 4720000 | Q16: BC200857 | R16: =IFERROR(INDEX(Tableau2[[ID BC UNIQUE]:[MONTANT HT VALIDE]],MATCH(Tableau6[[#This Row],[N° BC]],Tableau2[ID BC UNIQUE],0),6),0) -> 4000000 | S16: =IFERROR(INDEX(Tableau2[[DATE]:[DELAIS DE PAIEMENT FACTURES EN JOUR]],MATCH(Tableau6[[#This Row],[N° BC]],Tableau2[ID BC UNIQUE],0),5),0) -> 30 | T16: =IF(ISBLANK(Tableau6[[#This Row],[DATE DE DEPOT]]),"",Tableau6[[#This Row],[DATE DE DEPOT]]+Tableau6[[#This Row],[DELAI]]) -> 45710 | U16: =+IF(AND(W16=0,Tableau6[[#This Row],[DATE LIMITE]]<TODAY()),TODAY()-Tableau6[[#This Row],[DATE LIMITE]],0) -> 0 | V16: =IF(Tableau6[[#This Row],[DATE LIMITE]]>=TODAY(),"NON ECHUE",IF(Tableau6[[#This Row],[MONTANT HT]]<0,IF(ISNUMBER(MATCH(-Tableau6[[#This Row],[MONTANT HT]],Tableau6[MONTANT HT],0)),"AVOIR TOTAL","AVOIR PARTIEL"),IF(AND(ISNUMBER(MATCH(-Tableau6[[#This Row],[MONTANT HT]],Tableau6[MONTANT HT],0)),(Tableau6[[#This Row],[ACOMPTE SUR TTC]]+Tableau6[[#This Row],[MONTANT PAYE]])=0),"FACTURE ANNULEE",IF(Tableau6[[#This Row],[ACOMPTE SUR TTC]]+Tableau6[[#This Row],[MONTANT PAYE]]=0,"ECHUE NON REGLEE",IF(Tableau6[[#This Row],[ACOMPTE SUR TTC]]+Tableau6[[#This Row],[MONTANT PAYE]]=Tableau6[[#This Row],[NET A PAYER]],"PAYE",IF(Tableau6[[#This Row],[ACOMPTE SUR TTC]]+Tableau6[[#This Row],[MONTANT PAYE]]<Tableau6[[#This Row],[NET A PAYER]],"PAIEMENT PARTIEL","TROP PAYE")))))) -> PAYE | W16: =SUMIF(Tableau3[FACTURE],Tableau6[[#This Row],[NUM DE FACTURE]],Tableau3[MONTANT TTC]) -> 4720000 | Y16: =+Tableau6[[#This Row],[NET A PAYER]]-Tableau6[[#This Row],[MONTANT PAYE]] -> 0
A17: KENAM S | B17: 45680 | C17: 45680 | D17: 220 | E17: PFO CONSTRUCTION | F17: LOCATION DE CAMIONS | G17: 257B0207 | H17: TVAF | J17: 400000 | K17: =+Tableau6[[#This Row],[MONTANT HT BIEN]]+Tableau6[[#This Row],[MONTANT HT SERVICE]] -> 400000 | L17: 0 | M17: =+IFERROR(IF(Tableau6[[#This Row],[CODE TVA]]="TVAF",Tableau6[[#This Row],[MONTANT HT]]*0.18,0),0) -> 72000 | N17: =Tableau6[[#This Row],[MONTANT HT]]+Tableau6[[#This Row],[TVA]]-Tableau6[[#This Row],[ACOMPTE SUR HT]] -> 472000 | P17: =+ROUND(Tableau6[[#This Row],[MONTANT TTC]]-Tableau6[[#This Row],[ACOMPTE SUR TTC]],0) -> 472000 | Q17: BC200858 | R17: =IFERROR(INDEX(Tableau2[[ID BC UNIQUE]:[MONTANT HT VALIDE]],MATCH(Tableau6[[#This Row],[N° BC]],Tableau2[ID BC UNIQUE],0),6),0) -> 400000 | S17: =IFERROR(INDEX(Tableau2[[DATE]:[DELAIS DE PAIEMENT FACTURES EN JOUR]],MATCH(Tableau6[[#This Row],[N° BC]],Tableau2[ID BC UNIQUE],0),5),0) -> 30 | T17: =IF(ISBLANK(Tableau6[[#This Row],[DATE DE DEPOT]]),"",Tableau6[[#This Row],[DATE DE DEPOT]]+Tableau6[[#This Row],[DELAI]]) -> 45710 | U17: =+IF(AND(W17=0,Tableau6[[#This Row],[DATE LIMITE]]<TODAY()),TODAY()-Tableau6[[#This Row],[DATE LIMITE]],0) -> 0 | V17: =IF(Tableau6[[#This Row],[DATE LIMITE]]>=TODAY(),"NON ECHUE",IF(Tableau6[[#This Row],[MONTANT HT]]<0,IF(ISNUMBER(MATCH(-Tableau6[[#This Row],[MONTANT HT]],Tableau6[MONTANT HT],0)),"AVOIR TOTAL","AVOIR PARTIEL"),IF(AND(ISNUMBER(MATCH(-Tableau6[[#This Row],[MONTANT HT]],Tableau6[MONTANT HT],0)),(Tableau6[[#This Row],[ACOMPTE SUR TTC]]+Tableau6[[#This Row],[MONTANT PAYE]])=0),"FACTURE ANNULEE",IF(Tableau6[[#This Row],[ACOMPTE SUR TTC]]+Tableau6[[#This Row],[MONTANT PAYE]]=0,"ECHUE NON REGLEE",IF(Tableau6[[#This Row],[ACOMPTE SUR TTC]]+Tableau6[[#This Row],[MONTANT PAYE]]=Tableau6[[#This Row],[NET A PAYER]],"PAYE",IF(Tableau6[[#This Row],[ACOMPTE SUR TTC]]+Tableau6[[#This Row],[MONTANT PAYE]]<Tableau6[[#This Row],[NET A PAYER]],"PAIEMENT PARTIEL","TROP PAYE")))))) -> PAYE | W17: =SUMIF(Tableau3[FACTURE],Tableau6[[#This Row],[NUM DE FACTURE]],Tableau3[MONTANT TTC]) -> 472000 | Y17: =+Tableau6[[#This Row],[NET A PAYER]]-Tableau6[[#This Row],[MONTANT PAYE]] -> 0
A18: KENAM S | B18: 45680 | C18: 45680 | D18: 221 | E18: PFO CONSTRUCTION | F18: LOCATION DE CAMIONS | G18: 257B0203 | H18: TVAF | J18: 1400000 | K18: =+Tableau6[[#This Row],[MONTANT HT BIEN]]+Tableau6[[#This Row],[MONTANT HT SERVICE]] -> 1400000 | L18: 0 | M18: =+IFERROR(IF(Tableau6[[#This Row],[CODE TVA]]="TVAF",Tableau6[[#This Row],[MONTANT HT]]*0.18,0),0) -> 252000 | N18: =Tableau6[[#This Row],[MONTANT HT]]+Tableau6[[#This Row],[TVA]]-Tableau6[[#This Row],[ACOMPTE SUR HT]] -> 1652000 | P18: =+ROUND(Tableau6[[#This Row],[MONTANT TTC]]-Tableau6[[#This Row],[ACOMPTE SUR TTC]],0) -> 1652000 | Q18: BC200839 | R18: =IFERROR(INDEX(Tableau2[[ID BC UNIQUE]:[MONTANT HT VALIDE]],MATCH(Tableau6[[#This Row],[N° BC]],Tableau2[ID BC UNIQUE],0),6),0) -> 1400000 | S18: =IFERROR(INDEX(Tableau2[[DATE]:[DELAIS DE PAIEMENT FACTURES EN JOUR]],MATCH(Tableau6[[#This Row],[N° BC]],Tableau2[ID BC UNIQUE],0),5),0) -> 30 | T18: =IF(ISBLANK(Tableau6[[#This Row],[DATE DE DEPOT]]),"",Tableau6[[#This Row],[DATE DE DEPOT]]+Tableau6[[#This Row],[DELAI]]) -> 45710 | U18: =+IF(AND(W18=0,Tableau6[[#This Row],[DATE LIMITE]]<TODAY()),TODAY()-Tableau6[[#This Row],[DATE LIMITE]],0) -> 0 | V18: =IF(Tableau6[[#This Row],[DATE LIMITE]]>=TODAY(),"NON ECHUE",IF(Tableau6[[#This Row],[MONTANT HT]]<0,IF(ISNUMBER(MATCH(-Tableau6[[#This Row],[MONTANT HT]],Tableau6[MONTANT HT],0)),"AVOIR TOTAL","AVOIR PARTIEL"),IF(AND(ISNUMBER(MATCH(-Tableau6[[#This Row],[MONTANT HT]],Tableau6[MONTANT HT],0)),(Tableau6[[#This Row],[ACOMPTE SUR TTC]]+Tableau6[[#This Row],[MONTANT PAYE]])=0),"FACTURE ANNULEE",IF(Tableau6[[#This Row],[ACOMPTE SUR TTC]]+Tableau6[[#This Row],[MONTANT PAYE]]=0,"ECHUE NON REGLEE",IF(Tableau6[[#This Row],[ACOMPTE SUR TTC]]+Tableau6[[#This Row],[MONTANT PAYE]]=Tableau6[[#This Row],[NET A PAYER]],"PAYE",IF(Tableau6[[#This Row],[ACOMPTE SUR TTC]]+Tableau6[[#This Row],[MONTANT PAYE]]<Tableau6[[#This Row],[NET A PAYER]],"PAIEMENT PARTIEL","TROP PAYE")))))) -> PAYE | W18: =SUMIF(Tableau3[FACTURE],Tableau6[[#This Row],[NUM DE FACTURE]],Tableau3[MONTANT TTC]) -> 1652000 | Y18: =+Tableau6[[#This Row],[NET A PAYER]]-Tableau6[[#This Row],[MONTANT PAYE]] -> 0
A19: KENAM S | B19: 45680 | C19: 45680 | D19: 222 | E19: PFO CONSTRUCTION | F19: LOCATION DE CAMIONS | G19: 257B0200 | H19: TVAF | J19: 3800000 | K19: =+Tableau6[[#This Row],[MONTANT HT BIEN]]+Tableau6[[#This Row],[MONTANT HT SERVICE]] -> 3800000 | L19: 0 | M19: =+IFERROR(IF(Tableau6[[#This Row],[CODE TVA]]="TVAF",Tableau6[[#This Row],[MONTANT HT]]*0.18,0),0) -> 684000 | N19: =Tableau6[[#This Row],[MONTANT HT]]+Tableau6[[#This Row],[TVA]]-Tableau6[[#This Row],[ACOMPTE SUR HT]] -> 4484000 | P19: =+ROUND(Tableau6[[#This Row],[MONTANT TTC]]-Tableau6[[#This Row],[ACOMPTE SUR TTC]],0) -> 4484000 | Q19: BC200840 | R19: =IFERROR(INDEX(Tableau2[[ID BC UNIQUE]:[MONTANT HT VALIDE]],MATCH(Tableau6[[#This Row],[N° BC]],Tableau2[ID BC UNIQUE],0),6),0) -> 3800000 | S19: =IFERROR(INDEX(Tableau2[[DATE]:[DELAIS DE PAIEMENT FACTURES EN JOUR]],MATCH(Tableau6[[#This Row],[N° BC]],Tableau2[ID BC UNIQUE],0),5),0) -> 30 | T19: =IF(ISBLANK(Tableau6[[#This Row],[DATE DE DEPOT]]),"",Tableau6[[#This Row],[DATE DE DEPOT]]+Tableau6[[#This Row],[DELAI]]) -> 45710 | U19: =+IF(AND(W19=0,Tableau6[[#This Row],[DATE LIMITE]]<TODAY()),TODAY()-Tableau6[[#This Row],[DATE LIMITE]],0) -> 0 | V19: =IF(Tableau6[[#This Row],[DATE LIMITE]]>=TODAY(),"NON ECHUE",IF(Tableau6[[#This Row],[MONTANT HT]]<0,IF(ISNUMBER(MATCH(-Tableau6[[#This Row],[MONTANT HT]],Tableau6[MONTANT HT],0)),"AVOIR TOTAL","AVOIR PARTIEL"),IF(AND(ISNUMBER(MATCH(-Tableau6[[#This Row],[MONTANT HT]],Tableau6[MONTANT HT],0)),(Tableau6[[#This Row],[ACOMPTE SUR TTC]]+Tableau6[[#This Row],[MONTANT PAYE]])=0),"FACTURE ANNULEE",IF(Tableau6[[#This Row],[ACOMPTE SUR TTC]]+Tableau6[[#This Row],[MONTANT PAYE]]=0,"ECHUE NON REGLEE",IF(Tableau6[[#This Row],[ACOMPTE SUR TTC]]+Tableau6[[#This Row],[MONTANT PAYE]]=Tableau6[[#This Row],[NET A PAYER]],"PAYE",IF(Tableau6[[#This Row],[ACOMPTE SUR TTC]]+Tableau6[[#This Row],[MONTANT PAYE]]<Tableau6[[#This Row],[NET A PAYER]],"PAIEMENT PARTIEL","TROP PAYE")))))) -> PAYE | W19: =SUMIF(Tableau3[FACTURE],Tableau6[[#This Row],[NUM DE FACTURE]],Tableau3[MONTANT TTC]) -> 4484000 | Y19: =+Tableau6[[#This Row],[NET A PAYER]]-Tableau6[[#This Row],[MONTANT PAYE]] -> 0
A20: KENAM S | B20: 45680 | C20: 45680 | D20: 224 | E20: PFO CONSTRUCTION | F20: LOCATION DE CAMIONS | G20: 257B0200 | H20: TVAF | J20: 2700000 | K20: =+Tableau6[[#This Row],[MONTANT HT BIEN]]+Tableau6[[#This Row],[MONTANT HT SERVICE]] -> 2700000 | L20: 0 | M20: =+IFERROR(IF(Tableau6[[#This Row],[CODE TVA]]="TVAF",Tableau6[[#This Row],[MONTANT HT]]*0.18,0),0) -> 486000 | N20: =Tableau6[[#This Row],[MONTANT HT]]+Tableau6[[#This Row],[TVA]]-Tableau6[[#This Row],[ACOMPTE SUR HT]] -> 3186000 | P20: =+ROUND(Tableau6[[#This Row],[MONTANT TTC]]-Tableau6[[#This Row],[ACOMPTE SUR TTC]],0) -> 3186000 | Q20: BC200841 | R20: =IFERROR(INDEX(Tableau2[[ID BC UNIQUE]:[MONTANT HT VALIDE]],MATCH(Tableau6[[#This Row],[N° BC]],Tableau2[ID BC UNIQUE],0),6),0) -> 2700000 | S20: =IFERROR(INDEX(Tableau2[[DATE]:[DELAIS DE PAIEMENT FACTURES EN JOUR]],MATCH(Tableau6[[#This Row],[N° BC]],Tableau2[ID BC UNIQUE],0),5),0) -> 30 | T20: =IF(ISBLANK(Tableau6[[#This Row],[DATE DE DEPOT]]),"",Tableau6[[#This Row],[DATE DE DEPOT]]+Tableau6[[#This Row],[DELAI]]) -> 45710 | U20: =+IF(AND(W20=0,Tableau6[[#This Row],[DATE LIMITE]]<TODAY()),TODAY()-Tableau6[[#This Row],[DATE LIMITE]],0) -> 0 | V20: =IF(Tableau6[[#This Row],[DATE LIMITE]]>=TODAY(),"NON ECHUE",IF(Tableau6[[#This Row],[MONTANT HT]]<0,IF(ISNUMBER(MATCH(-Tableau6[[#This Row],[MONTANT HT]],Tableau6[MONTANT HT],0)),"AVOIR TOTAL","AVOIR PARTIEL"),IF(AND(ISNUMBER(MATCH(-Tableau6[[#This Row],[MONTANT HT]],Tableau6[MONTANT HT],0)),(Tableau6[[#This Row],[ACOMPTE SUR TTC]]+Tableau6[[#This Row],[MONTANT PAYE]])=0),"FACTURE ANNULEE",IF(Tableau6[[#This Row],[ACOMPTE SUR TTC]]+Tableau6[[#This Row],[MONTANT PAYE]]=0,"ECHUE NON REGLEE",IF(Tableau6[[#This Row],[ACOMPTE SUR TTC]]+Tableau6[[#This Row],[MONTANT PAYE]]=Tableau6[[#This Row],[NET A PAYER]],"PAYE",IF(Tableau6[[#This Row],[ACOMPTE SUR TTC]]+Tableau6[[#This Row],[MONTANT PAYE]]<Tableau6[[#This Row],[NET A PAYER]],"PAIEMENT PARTIEL","TROP PAYE")))))) -> PAYE | W20: =SUMIF(Tableau3[FACTURE],Tableau6[[#This Row],[NUM DE FACTURE]],Tableau3[MONTANT TTC]) -> 3186000 | Y20: =+Tableau6[[#This Row],[NET A PAYER]]-Tableau6[[#This Row],[MONTANT PAYE]] -> 0
