Workbook
Name \0: #REF!
Name \1: #REF!
Name \a: #REF!
Name \b: #REF!
Name \C: #REF!
Name \D: #REF!
Name \e: #REF!
Name \f: #REF!
Name \h: #REF!
Name \i: #REF!
Name \j: #REF!
Name \l: #REF!
Name \m: #REF!
Name \n: #REF!
Name \o: #REF!
Name \p: #REF!
Name \s: #REF!
Name \t: #REF!
Name \u: #REF!
Name \z: #REF!
Name ______________tap2: #REF!
Name _____________tap2: #REF!
Name ____________tap2: #REF!
Name ___________tap2: #REF!
Name __________tap2: #REF!
Name _________tap2: #REF!
Name ________tap2: #REF!
Name _______tap2: #REF!
Name ______tap2: #REF!
Name _____tap2: #REF!
Name ____tap2: #REF!
Name ___tap2: #REF!
Name __bed53: #REF!
Name __cav1: #REF!
Name __COM2: #REF!
Name __DJI2: #REF!
Name __EAO2: #REF!
Name __EAR2: #REF!
Name __ETH2: #REF!
Name __KE2: #REF!
Name __L: #REF!
Name __MAU2: #REF!
Name __MD2: #REF!
Name __MS2: #REF!
Name __RE2: #REF!
Name __SEY2: #REF!
Name __SM2: #REF!
Name __SOM2: #REF!
Name __tap2: #REF!
Name __tot1: #REF!
Name __tot2: #REF!
Name __TZ2: #REF!
Name __UG2: #REF!
Name _0_09_84: #REF!
Name _1: #REF!
Name _10003: #REF!
Name _10004: #REF!
Name _10006: #REF!
Name _10012: #REF!
Name _10015: #REF!

Sheet FACTURES FOURNISSEURS
J1: TOTAL | K1: =+SUBTOTAL(9,Tableau330[MONTANT HT BIENS]) -> 46204913 | L1: =+SUBTOTAL(9,Tableau330[[MONTANT HT SERVICES ]]) -> 23488773 | M1: =+SUBTOTAL(9,Tableau330[MONTANT HT]) -> 3.9791433e+08 | N1: =+SUBTOTAL(9,Tableau330[TVA]) -> 46846525 | O1: =+SUBTOTAL(9,Tableau330[MONTANT TTC]) -> 4.4476086e+08 | P1: =+SUBTOTAL(9,Tableau330[[TIMBRE ]]) -> 11999 | Q1: =+SUBTOTAL(9,Tableau330[AUTRES TAXES]) -> 37258 | R1: =+SUBTOTAL(9,Tableau330[MONTANT TTC]) -> 4.4476086e+08 | S1: =+SUBTOTAL(9,Tableau330[MONTANT PAYE]) -> 4.2783171e+08 | T1: =+SUBTOTAL(9,Tableau330[SOLDE]) -> 16978410
A2: DATE | B2: PERIODE | C2: TYPE F/ | D2: N° F/ | E2: FOURNISSEURS | F2: NCC | G2: REGIME | H2: DESIGNATION | I2: CODE TVA | J2: PRORATA D | K2: MONTANT HT BIENS | L2: MONTANT HT SERVICES | M2: MONTANT HT | N2: TVA | O2: MONTANT TTC | P2: TIMBRE | Q2: AUTRES TAXES | R2: NET A PAYER | S2: MONTANT PAYE | T2: SOLDE | U2: DELAI_PAIEMENT | V2: DATE ECHEANCE | W2: NATURE COMPTABLE | X2: PAYE | Y2: MODE | Z2: REFERENCE REGLEMENT | AA2: OBSERVATIONS
A3: 45609 | B3: =IF(ISBLANK(Tableau330[[#This Row],[DATE ]]),"",UPPER(PROPER(TEXT(Tableau330[[#This Row],[DATE ]],"mmmm yyyy")))) -> NOVEMBRE 2024 | C3: FN | D3: 013657 | E3: INDUSTRAP | F3: 9000831 C | H3: ACHAT DE COLORANT 200 ML | I3: TVA | J3: 1 | M3: 931016 | N3: =+IF(Tableau330[[#This Row],[CODE TVA]]="",0,ROUND(Tableau330[[#This Row],[MONTANT HT]]*0.18*Tableau330[[#This Row],[PRORATA D]],1)) -> 167582.9 | O3: =+IFERROR(Tableau330[[#This Row],[MONTANT HT]]+Tableau330[[#This Row],[TVA]],0) -> 1098598.9 | R3: =+Tableau330[[#This Row],[MONTANT TTC]]+Tableau330[[#This Row],[TIMBRE ]]+Tableau330[[#This Row],[AUTRES TAXES]] -> 1098598.9 | S3: 1098598.9 | T3: =+ROUND(Tableau330[[#This Row],[NET A PAYER]],0)-Tableau330[[#This Row],[MONTANT PAYE]] -> 0.12 | V3: =+Tableau330[[#This Row],[DELAI_PAIEMENT]]+Tableau330[[#This Row],[DATE ]] -> 45609
A4: 45619 | B4: =IF(ISBLANK(Tableau330[[#This Row],[DATE ]]),"",UPPER(PROPER(TEXT(Tableau330[[#This Row],[DATE ]],"mmmm yyyy")))) -> NOVEMBRE 2024 | C4: FN | D4: 022884 | E4: SPRIINT TECH | F4: 1106600 L | H4: E/G AV AERO ECO 450MM | I4: TVA | J4: 1 | M4: 10928 | N4: =+IF(Tableau330[[#This Row],[CODE TVA]]="",0,ROUND(Tableau330[[#This Row],[MONTANT HT]]*0.18*Tableau330[[#This Row],[PRORATA D]],1)) -> 1967 | O4: =+IFERROR(Tableau330[[#This Row],[MONTANT HT]]+Tableau330[[#This Row],[TVA]],0) -> 12895 | R4: =+Tableau330[[#This Row],[MONTANT TTC]]+Tableau330[[#This Row],[TIMBRE ]]+Tableau330[[#This Row],[AUTRES TAXES]] -> 12895 | S4: 12895 | T4: =+ROUND(Tableau330[[#This Row],[NET A PAYER]],0)-Tableau330[[#This Row],[MONTANT PAYE]] -> 0 | V4: =+Tableau330[[#This Row],[DELAI_PAIEMENT]]+Tableau330[[#This Row],[DATE ]] -> 45619
A5: 45623 | B5: =IF(ISBLANK(Tableau330[[#This Row],[DATE ]]),"",UPPER(PROPER(TEXT(Tableau330[[#This Row],[DATE ]],"mmmm yyyy")))) -> NOVEMBRE 2024 | C5: NON-FN | D5: 8584501 | E5: ETS KIRAKOYA TIDIANE | F5: 1217411 Q | H5: ACHAT PNEU 13R225, 315/80R225 | M5: 525000 | N5: =+IF(Tableau330[[#This Row],[CODE TVA]]="",0,ROUND(Tableau330[[#This Row],[MONTANT HT]]*0.18*Tableau330[[#This Row],[PRORATA D]],1)) -> 0 | O5: =+IFERROR(Tableau330[[#This Row],[MONTANT HT]]+Tableau330[[#This Row],[TVA]],0) -> 525000 | R5: =+Tableau330[[#This Row],[MONTANT TTC]]+Tableau330[[#This Row],[TIMBRE ]]+Tableau330[[#This Row],[AUTRES TAXES]] -> 525000 | S5: 525000 | T5: =+ROUND(Tableau330[[#This Row],[NET A PAYER]],0)-Tableau330[[#This Row],[MONTANT PAYE]] -> 0 | V5: =+Tableau330[[#This Row],[DELAI_PAIEMENT]]+Tableau330[[#This Row],[DATE ]] -> 45623
A6: 45626 | B6: =IF(ISBLANK(Tableau330[[#This Row],[DATE ]]),"",UPPER(PROPER(TEXT(Tableau330[[#This Row],[DATE ]],"mmmm yyyy")))) -> NOVEMBRE 2024 | C6: FN | D6: 0006110 | E6: PACSI | F6: 1303973 A | G6: RNI | H6: ACHAT CORDEAU, BATTERIE, MOTEUR, DISQUE, CARREAUX-EX_2024 | I6: TVA | J6: 1 | M6: 120512 | N6: =+IF(Tableau330[[#This Row],[CODE TVA]]="",0,ROUND(Tableau330[[#This Row],[MONTANT HT]]*0.18*Tableau330[[#This Row],[PRORATA D]],1)) -> 21692.2 | O6: =+IFERROR(Tableau330[[#This Row],[MONTANT HT]]+Tableau330[[#This Row],[TVA]],0) -> 142204.2 | Q6: 7110 | R6: =+Tableau330[[#This Row],[MONTANT TTC]]+Tableau330[[#This Row],[TIMBRE ]]+Tableau330[[#This Row],[AUTRES TAXES]] -> 149314.2 | T6: =+ROUND(Tableau330[[#This Row],[NET A PAYER]],0)-Tableau330[[#This Row],[MONTANT PAYE]] -> 149314 | V6: =+Tableau330[[#This Row],[DELAI_PAIEMENT]]+Tableau330[[#This Row],[DATE ]] -> 45626 | X6: OUI_T | Y6: ESPECES
A7: 45645 | B7: =IF(ISBLANK(Tableau330[[#This Row],[DATE ]]),"",UPPER(PROPER(TEXT(Tableau330[[#This Row],[DATE ]],"mmmm yyyy")))) -> DÉCEMBRE 2024 | C7: FN | D7: 007009 | E7: RIMCO-SETACI | F7: 9809714 J | G7: RNI | H7: SINOTRUK BENNE 8*4 HOWO_782 & 783 | I7: TVA | J7: 1 | M7: 88135593 | N7: =+IF(Tableau330[[#This Row],[CODE TVA]]="",0,ROUND(Tableau330[[#This Row],[MONTANT HT]]*0.18*Tableau330[[#This Row],[PRORATA D]],1)) -> 15864407 | O7: =+IFERROR(Tableau330[[#This Row],[MONTANT HT]]+Tableau330[[#This Row],[TVA]],0) -> 1.04e+08 | R7: =+Tableau330[[#This Row],[MONTANT TTC]]+Tableau330[[#This Row],[TIMBRE ]]+Tableau330[[#This Row],[AUTRES TAXES]] -> 1.04e+08 | S7: 1.04e+08 | T7: =+ROUND(Tableau330[[#This Row],[NET A PAYER]],0)-Tableau330[[#This Row],[MONTANT PAYE]] -> 0.26000001 | V7: =+Tableau330[[#This Row],[DELAI_PAIEMENT]]+Tableau330[[#This Row],[DATE ]] -> 45645
A8: 45660 | B8: =IF(ISBLANK(Tableau330[[#This Row],[DATE ]]),"",UPPER(PROPER(TEXT(Tableau330[[#This Row],[DATE ]],"mmmm yyyy")))) -> JANVIER 2025 | C8: FN | D8: 0009609 | E8: AL FAYSAL SARL | F8: 1648055 N | G8: RNI | H8: TILAPIA | M8: 14000 | N8: =+IF(Tableau330[[#This Row],[CODE TVA]]="",0,ROUND(Tableau330[[#This Row],[MONTANT HT]]*0.18*Tableau330[[#This Row],[PRORATA D]],1)) -> 0 | O8: =+IFERROR(Tableau330[[#This Row],[MONTANT HT]]+Tableau330[[#This Row],[TVA]],0) -> 14000 | R8: =+Tableau330[[#This Row],[MONTANT TTC]]+Tableau330[[#This Row],[TIMBRE ]]+Tableau330[[#This Row],[AUTRES TAXES]] -> 14000 | S8: 14000 | T8: =+ROUND(Tableau330[[#This Row],[NET A PAYER]],0)-Tableau330[[#This Row],[MONTANT PAYE]] -> 0 | V8: =+Tableau330[[#This Row],[DELAI_PAIEMENT]]+Tableau330[[#This Row],[DATE ]] -> 45660
A9: 45660 | B9: =IF(ISBLANK(Tableau330[[#This Row],[DATE ]]),"",UPPER(PROPER(TEXT(Tableau330[[#This Row],[DATE ]],"mmmm yyyy")))) -> JANVIER 2025 | C9: FN | D9: 007123 | E9: PROSUMA | F9: 5011806 N | H9: RIZ | I9: TVA | M9: 34000 | N9: =+IF(Tableau330[[#This Row],[CODE TVA]]="",0,ROUND(Tableau330[[#This Row],[MONTANT HT]]*0.18*Tableau330[[#This Row],[PRORATA D]],1)) -> 0 | O9: =+IFERROR(Tableau330[[#This Row],[MONTANT HT]]+Tableau330[[#This Row],[TVA]],0) -> 34000 | R9: =+Tableau330[[#This Row],[MONTANT TTC]]+Tableau330[[#This Row],[TIMBRE ]]+Tableau330[[#This Row],[AUTRES TAXES]] -> 34000 | S9: 34000 | T9: =+ROUND(Tableau330[[#This Row],[NET A PAYER]],0)-Tableau330[[#This Row],[MONTANT PAYE]] -> 0 | V9: =+Tableau330[[#This Row],[DELAI_PAIEMENT]]+Tableau330[[#This Row],[DATE ]] -> 45660
A10: 45661 | B10: =IF(ISBLANK(Tableau330[[#This Row],[DATE ]]),"",UPPER(PROPER(TEXT(Tableau330[[#This Row],[DATE ]],"mmmm yyyy")))) -> JANVIER 2025 | C10: NON-FN | D10: 0078861 | E10: SOUADIK SBM | F10: 2300142 N | H10: ACHAT CARBURANT | M10: 498000 | N10: =+IF(Tableau330[[#This Row],[CODE TVA]]="",0,ROUND(Tableau330[[#This Row],[MONTANT HT]]*0.18*Tableau330[[#This Row],[PRORATA D]],1)) -> 0 | O10: =+IFERROR(Tableau330[[#This Row],[MONTANT HT]]+Tableau330[[#This Row],[TVA]],0) -> 498000 | R10: =+Tableau330[[#This Row],[MONTANT TTC]]+Tableau330[[#This Row],[TIMBRE ]]+Tableau330[[#This Row],[AUTRES TAXES]] -> 498000 | S10: 498000 | T10: =+ROUND(Tableau330[[#This Row],[NET A PAYER]],0)-Tableau330[[#This Row],[MONTANT PAYE]] -> 0 | V10: =+Tableau330[[#This Row],[DELAI_PAIEMENT]]+Tableau330[[#This Row],[DATE ]] -> 45661
A11: 45661 | B11: =IF(ISBLANK(Tableau330[[#This Row],[DATE ]]),"",UPPER(PROPER(TEXT(Tableau330[[#This Row],[DATE ]],"mmmm yyyy")))) -> JANVIER 2025 | C11: FN | D11: 022678 | E11: PROSUMA | F11: 5011806 N | H11: ACHAT SUCRE, EAU, DESO, ASSIETTES | I11: TVA | J11: 1 | M11: 10974 | N11: =+IF(Tableau330[[#This Row],[CODE TVA]]="",0,ROUND(Tableau330[[#This Row],[MONTANT HT]]*0.18*Tableau330[[#This Row],[PRORATA D]],1)) -> 1975.3 | O11: =+IFERROR(Tableau330[[#This Row],[MONTANT HT]]+Tableau330[[#This Row],[TVA]],0) -> 12949.3 | R11: =+Tableau330[[#This Row],[MONTANT TTC]]+Tableau330[[#This Row],[TIMBRE ]]+Tableau330[[#This Row],[AUTRES TAXES]] -> 12949.3 | S11: 12949 | T11: =+ROUND(Tableau330[[#This Row],[NET A PAYER]],0)-Tableau330[[#This Row],[MONTANT PAYE]] -> 0 | V11: =+Tableau330[[#This Row],[DELAI_PAIEMENT]]+Tableau330[[#This Row],[DATE ]] -> 45661
A12: 45663 | B12: =IF(ISBLANK(Tableau330[[#This Row],[DATE ]]),"",UPPER(PROPER(TEXT(Tableau330[[#This Row],[DATE ]],"mmmm yyyy")))) -> JANVIER 2025 | C12: FN | D12: 016310 | E12: INDUSTRAP | F12: 9000831 C | H12: CIMENT CAROCOL BLANC 25 KG | I12: TVA | J12: 1 | M12: 201271 | N12: =+IF(Tableau330[[#This Row],[CODE TVA]]="",0,ROUND(Tableau330[[#This Row],[MONTANT HT]]*0.18*Tableau330[[#This Row],[PRORATA D]],1)) -> 36228.8 | O12: =+IFERROR(Tableau330[[#This Row],[MONTANT HT]]+Tableau330[[#This Row],[TVA]],0) -> 237499.8 | R12: =+Tableau330[[#This Row],[MONTANT TTC]]+Tableau330[[#This Row],[TIMBRE ]]+Tableau330[[#This Row],[AUTRES TAXES]] -> 237499.8 | S12: 237499.78 | T12: =+ROUND(Tableau330[[#This Row],[NET A PAYER]],0)-Tableau330[[#This Row],[MONTANT PAYE]] -> 0.22 | V12: =+Tableau330[[#This Row],[DELAI_PAIEMENT]]+Tableau330[[#This Row],[DATE ]] -> 45663
A13: 45663 | B13: =IF(ISBLANK(Tableau330[[#This Row],[DATE ]]),"",UPPER(PROPER(TEXT(Tableau330[[#This Row],[DATE ]],"mmmm yyyy")))) -> JANVIER 2025 | C13: FN | D13: 016311 | E13: INDUSTRAP | F13: 9000831 C | H13: TRAPEAU INT 30 KG | I13: TVA | J13: 1 | M13: 550847.5 | N13: =+IF(Tableau330[[#This Row],[CODE TVA]]="",0,ROUND(Tableau330[[#This Row],[MONTANT HT]]*0.18*Tableau330[[#This Row],[PRORATA D]],1)) -> 99152.6 | O13: =+IFERROR(Tableau330[[#This Row],[MONTANT HT]]+Tableau330[[#This Row],[TVA]],0) -> 650000.1 | R13: =+Tableau330[[#This Row],[MONTANT TTC]]+Tableau330[[#This Row],[TIMBRE ]]+Tableau330[[#This Row],[AUTRES TAXES]] -> 650000.1 | S13: 650000 | T13: =+ROUND(Tableau330[[#This Row],[NET A PAYER]],0)-Tableau330[[#This Row],[MONTANT PAYE]] -> 0 | V13: =+Tableau330[[#This Row],[DELAI_PAIEMENT]]+Tableau330[[#This Row],[DATE ]] -> 45663
A14: 45664 | B14: =IF(ISBLANK(Tableau330[[#This Row],[DATE ]]),"",UPPER(PROPER(TEXT(Tableau330[[#This Row],[DATE ]],"mmmm yyyy")))) -> JANVIER 2025 | C14: FN | D14: 0003828 | E14: CHINA MART | F14: 2215123 N | H14: CYLINDRE, SAC CADEAU, ENVELOPPE | M14: 8360 | N14: =+IF(Tableau330[[#This Row],[CODE TVA]]="",0,ROUND(Tableau330[[#This Row],[MONTANT HT]]*0.18*Tableau330[[#This Row],[PRORATA D]],1)) -> 0 | O14: =+IFERROR(Tableau330[[#This Row],[MONTANT HT]]+Tableau330[[#This Row],[TVA]],0) -> 8360 | R14: =+Tableau330[[#This Row],[MONTANT TTC]]+Tableau330[[#This Row],[TIMBRE ]]+Tableau330[[#This Row],[AUTRES TAXES]] -> 8360 | S14: 8360 | T14: =+ROUND(Tableau330[[#This Row],[NET A PAYER]],0)-Tableau330[[#This Row],[MONTANT PAYE]] -> 0 | V14: =+Tableau330[[#This Row],[DELAI_PAIEMENT]]+Tableau330[[#This Row],[DATE ]] -> 45664
A15: 45665 | B15: =IF(ISBLANK(Tableau330[[#This Row],[DATE ]]),"",UPPER(PROPER(TEXT(Tableau330[[#This Row],[DATE ]],"mmmm yyyy")))) -> JANVIER 2025 | C15: NON-FN | D15: 25YPVFC50005 | E15: RIMCO-SETACI | F15: 9809714 J | G15: RNI | H15: 02 KIA K2700DC 4*4 | I15: TVA | J15: 1 | M15: 28305085 | N15: =+IF(Tableau330[[#This Row],[CODE TVA]]="",0,ROUND(Tableau330[[#This Row],[MONTANT HT]]*0.18*Tableau330[[#This Row],[PRORATA D]],1)) -> 5094915.3 | O15: =+IFERROR(Tableau330[[#This Row],[MONTANT HT]]+Tableau330[[#This Row],[TVA]],0) -> 33400000 | R15: =+Tableau330[[#This Row],[MONTANT TTC]]+Tableau330[[#This Row],[TIMBRE ]]+Tableau330[[#This Row],[AUTRES TAXES]] -> 33400000 | S15: 33400000 | T15: =+ROUND(Tableau330[[#This Row],[NET A PAYER]],0)-Tableau330[[#This Row],[MONTANT PAYE]] -> 0 | V15: =+Tableau330[[#This Row],[DELAI_PAIEMENT]]+Tableau330[[#This Row],[DATE ]] -> 45665 | AA15: DUPLICATA F/ EGAREE
A16: 45668 | B16: =IF(ISBLANK(Tableau330[[#This Row],[DATE ]]),"",UPPER(PROPER(TEXT(Tableau330[[#This Row],[DATE ]],"mmmm yyyy")))) -> JANVIER 2025 | C16: NON-FN | D16: 872824 | E16: 4LIFE IMPRIM | H16: AUTOCOLLANT, CALENDRIER, BLOC NOTE | M16: 1300000 | N16: =+IF(Tableau330[[#This Row],[CODE TVA]]="",0,ROUND(Tableau330[[#This Row],[MONTANT HT]]*0.18*Tableau330[[#This Row],[PRORATA D]],1)) -> 0 | O16: =+IFERROR(Tableau330[[#This Row],[MONTANT HT]]+Tableau330[[#This Row],[TVA]],0) -> 1300000 | R16: =+Tableau330[[#This Row],[MONTANT TTC]]+Tableau330[[#This Row],[TIMBRE ]]+Tableau330[[#This Row],[AUTRES TAXES]] -> 1300000 | S16: 1300000 | T16: =+ROUND(Tableau330[[#This Row],[NET A PAYER]],0)-Tableau330[[#This Row],[MONTANT PAYE]] -> 0 | V16: =+Tableau330[[#This Row],[DELAI_PAIEMENT]]+Tableau330[[#This Row],[DATE ]] -> 45668
A17: 45668 | B17: =IF(ISBLANK(Tableau330[[#This Row],[DATE ]]),"",UPPER(PROPER(TEXT(Tableau330[[#This Row],[DATE ]],"mmmm yyyy")))) -> JANVIER 2025 | C17: NON-FN | D17: 184337 | E17: BARRY OUSMANE | H17: COMPTEUR D'HEURE POUR CAMION | M17: 75000 | N17: =+IF(Tableau330[[#This Row],[CODE TVA]]="",0,ROUND(Tableau330[[#This Row],[MONTANT HT]]*0.18*Tableau330[[#This Row],[PRORATA D]],1)) -> 0 | O17: =+IFERROR(Tableau330[[#This Row],[MONTANT HT]]+Tableau330[[#This Row],[TVA]],0) -> 75000 | R17: =+Tableau330[[#This Row],[MONTANT TTC]]+Tableau330[[#This Row],[TIMBRE ]]+Tableau330[[#This Row],[AUTRES TAXES]] -> 75000 | S17: 75000 | T17: =+ROUND(Tableau330[[#This Row],[NET A PAYER]],0)-Tableau330[[#This Row],[MONTANT PAYE]] -> 0 | V17: =+Tableau330[[#This Row],[DELAI_PAIEMENT]]+Tableau330[[#This Row],[DATE ]] -> 45668
A18: 45671 | B18: =IF(ISBLANK(Tableau330[[#This Row],[DATE ]]),"",UPPER(PROPER(TEXT(Tableau330[[#This Row],[DATE ]],"mmmm yyyy")))) -> JANVIER 2025 | C18: NON-FN | D18: 125 | E18: COMPAGNIE IVOIRIENNE D'ELECTRICITE | F18: 9004996 S | G18: RNI | H18: CONSOMMATION D'ELECTRICITE DU 04/11/24 AU 04/01/25 | I18: TVA | J18: 1 | M18: 90600 | N18: =+IF(Tableau330[[#This Row],[CODE TVA]]="",0,ROUND(Tableau330[[#This Row],[MONTANT HT]]*0.18*Tableau330[[#This Row],[PRORATA D]],1)) -> 16308 | O18: =+IFERROR(Tableau330[[#This Row],[MONTANT HT]]+Tableau330[[#This Row],[TVA]],0) -> 106908 | P18: 500 | Q18: =1095+2260+2000 -> 5355 | R18: =+Tableau330[[#This Row],[MONTANT TTC]]+Tableau330[[#This Row],[TIMBRE ]]+Tableau330[[#This Row],[AUTRES TAXES]] -> 112763 | S18: 112763 | T18: =+ROUND(Tableau330[[#This Row],[NET A PAYER]],0)-Tableau330[[#This Row],[MONTANT PAYE]] -> 0 | V18: =+Tableau330[[#This Row],[DELAI_PAIEMENT]]+Tableau330[[#This Row],[DATE ]] -> 45671
A19: 45672 | B19: =IF(ISBLANK(Tableau330[[#This Row],[DATE ]]),"",UPPER(PROPER(TEXT(Tableau330[[#This Row],[DATE ]],"mmmm yyyy")))) -> JANVIER 2025 | C19: NON-FN | D19: 0673507 | E19: 4LIFE IMPRIM | H19: AUTOCLLANT, CALENDRIER BLOCS NOTES AGENDA | M19: 627500 | N19: =+IF(Tableau330[[#This Row],[CODE TVA]]="",0,ROUND(Tableau330[[#This Row],[MONTANT HT]]*0.18*Tableau330[[#This Row],[PRORATA D]],1)) -> 0 | O19: =+IFERROR(Tableau330[[#This Row],[MONTANT HT]]+Tableau330[[#This Row],[TVA]],0) -> 627500 | R19: =+Tableau330[[#This Row],[MONTANT TTC]]+Tableau330[[#This Row],[TIMBRE ]]+Tableau330[[#This Row],[AUTRES TAXES]] -> 627500 | S19: 627500 | T19: =+ROUND(Tableau330[[#This Row],[NET A PAYER]],0)-Tableau330[[#This Row],[MONTANT PAYE]] -> 0 | V19: =+Tableau330[[#This Row],[DELAI_PAIEMENT]]+Tableau330[[#This Row],[DATE ]] -> 45672
A20: 45673 | B20: =IF(ISBLANK(Tableau330[[#This Row],[DATE ]]),"",UPPER(PROPER(TEXT(Tableau330[[#This Row],[DATE ]],"mmmm yyyy")))) -> JANVIER 2025 | C20: FN | D20: 022691 | E20: PROSUMA | F20: 5011806 N | H20: PAPIER RAME, NETTOYANT SPRAY | I20: TVA | J20: 1 | M20: 8898 | N20: =+IF(Tableau330[[#This Row],[CODE TVA]]="",0,ROUND(Tableau330[[#This Row],[MONTANT HT]]*0.18*Tableau330[[#This Row],[PRORATA D]],1)) -> 1601.6 | O20: =+IFERROR(Tableau330[[#This Row],[MONTANT HT]]+Tableau330[[#This Row],[TVA]],0) -> 10499.6 | R20: =+Tableau330[[#This Row],[MONTANT TTC]]+Tableau330[[#This Row],[TIMBRE ]]+Tableau330[[#This Row],[AUTRES TAXES]] -> 10499.6 | S20: 10499.64 | T20: =+ROUND(Tableau330[[#This Row],[NET A PAYER]],0)-Tableau330[[#This Row],[MONTANT PAYE]] -> 0.36 | V20: =+Tableau330[[#This Row],[DELAI_PAIEMENT]]+Tableau330[[#This Row],[DATE ]] -> 45673
A21: 45677 | B21: =IF(ISBLANK(Tableau330[[#This Row],[DATE ]]),"",UPPER(PROPER(TEXT(Tableau330[[#This Row],[DATE ]],"mmmm yyyy")))) -> JANVIER 2025 | C21: FN | D21: 029790 | E21: SPRIINT TECH | F21: 1106600 L | G21: RNI | H21: BATTERIE 12 VT | I21: TVA | J21: 1 | M21: 347034 | N21: =+IF(Tableau330[[#This Row],[CODE TVA]]="",0,ROUND(Tableau330[[#This Row],[MONTANT HT]]*0.18*Tableau330[[#This Row],[PRORATA D]],1)) -> 62466.1 | O21: =+IFERROR(Tableau330[[#This Row],[MONTANT HT]]+Tableau330[[#This Row],[TVA]],0) -> 409500.1 | P21: 500 | Q21: 20475 | R21: =+Tableau330[[#This Row],[MONTANT TTC]]+Tableau330[[#This Row],[TIMBRE ]]+Tableau330[[#This Row],[AUTRES TAXES]] -> 430475.1 | S21: 430475 | T21: =+ROUND(Tableau330[[#This Row],[NET A PAYER]],0)-Tableau330[[#This Row],[MONTANT PAYE]] -> 0 | V21: =+Tableau330[[#This Row],[DELAI_PAIEMENT]]+Tableau330[[#This Row],[DATE ]] -> 45677
A22: 45678 | B22: =IF(ISBLANK(Tableau330[[#This Row],[DATE ]]),"",UPPER(PROPER(TEXT(Tableau330[[#This Row],[DATE ]],"mmmm yyyy")))) -> JANVIER 2025 | C22: FN | D22: 007704 | E22: RIMCO-SETACI | F22: 9809714 J | G22: RNI | H22: SINOTRUK BENNE 8*4 HOWO_784 | I22: TVA | J22: 1 | M22: 45338983 | N22: =+IF(Tableau330[[#This Row],[CODE TVA]]="",0,ROUND(Tableau330[[#This Row],[MONTANT HT]]*0.18*Tableau330[[#This Row],[PRORATA D]],1)) -> 8161016.9 | O22: =+IFERROR(Tableau330[[#This Row],[MONTANT HT]]+Tableau330[[#This Row],[TVA]],0) -> 53500000 | R22: =+Tableau330[[#This Row],[MONTANT TTC]]+Tableau330[[#This Row],[TIMBRE ]]+Tableau330[[#This Row],[AUTRES TAXES]] -> 53500000 | S22: 53500000 | T22: =+ROUND(Tableau330[[#This Row],[NET A PAYER]],0)-Tableau330[[#This Row],[MONTANT PAYE]] -> 0.060000002 | V22: =+Tableau330[[#This Row],[DELAI_PAIEMENT]]+Tableau330[[#This Row],[DATE ]] -> 45678
A23: 45678 | B23: =IF(ISBLANK(Tableau330[[#This Row],[DATE ]]),"",UPPER(PROPER(TEXT(Tableau330[[#This Row],[DATE ]],"mmmm yyyy")))) -> JANVIER 2025 | C23: FN | D23: 039129 | E23: BECROU SERVICES ET COMMUNICATION SARL | F23: 1801689 A | H23: CACHET 11 | M23: 20000 | N23: =+IF(Tableau330[[#This Row],[CODE TVA]]="",0,ROUND(Tableau330[[#This Row],[MONTANT HT]]*0.18*Tableau330[[#This Row],[PRORATA D]],1)) -> 0 | O23: =+IFERROR(Tableau330[[#This Row],[MONTANT HT]]+Tableau330[[#This Row],[TVA]],0) -> 20000 | R23: =+Tableau330[[#This Row],[MONTANT TTC]]+Tableau330[[#This Row],[TIMBRE ]]+Tableau330[[#This Row],[AUTRES TAXES]] -> 20000 | S23: 20000 | T23: =+ROUND(Tableau330[[#This Row],[NET A PAYER]],0)-Tableau330[[#This Row],[MONTANT PAYE]] -> 0 | V23: =+Tableau330[[#This Row],[DELAI_PAIEMENT]]+Tableau330[[#This Row],[DATE ]] -> 45678
A24: 45679 | B24: =IF(ISBLANK(Tableau330[[#This Row],[DATE ]]),"",UPPER(PROPER(TEXT(Tableau330[[#This Row],[DATE ]],"mmmm yyyy")))) -> JANVIER 2025 | C24: FN | D24: 173920 | E24: BUSINESS SERVICES INFORMATIQUES | F24: 1801689 A | H24: REPARATION D'IMPRIMANTE CANON | J24: 1 | M24: 15000 | N24: =+IF(Tableau330[[#This Row],[CODE TVA]]="",0,ROUND(Tableau330[[#This Row],[MONTANT HT]]*0.18*Tableau330[[#This Row],[PRORATA D]],1)) -> 0 | O24: =+IFERROR(Tableau330[[#This Row],[MONTANT HT]]+Tableau330[[#This Row],[TVA]],0) -> 15000 | R24: =+Tableau330[[#This Row],[MONTANT TTC]]+Tableau330[[#This Row],[TIMBRE ]]+Tableau330[[#This Row],[AUTRES TAXES]] -> 15000 | S24: 15000 | T24: =+ROUND(Tableau330[[#This Row],[NET A PAYER]],0)-Tableau330[[#This Row],[MONTANT PAYE]] -> 0 | V24: =+Tableau330[[#This Row],[DELAI_PAIEMENT]]+Tableau330[[#This Row],[DATE ]] -> 45679
A25: 45679 | B25: =IF(ISBLANK(Tableau330[[#This Row],[DATE ]]),"",UPPER(PROPER(TEXT(Tableau330[[#This Row],[DATE ]],"mmmm yyyy")))) -> JANVIER 2025 | C25: FN | D25: 029953 | E25: SPRIINT TECH | F25: 1106600 L | G25: RNI | H25: BATTERIE 12 VT | I25: TVA | J25: 1 | M25: 173517 | N25: =+IF(Tableau330[[#This Row],[CODE TVA]]="",0,ROUND(Tableau330[[#This Row],[MONTANT HT]]*0.18*Tableau330[[#This Row],[PRORATA D]],1)) -> 31233.1 | O25: =+IFERROR(Tableau330[[#This Row],[MONTANT HT]]+Tableau330[[#This Row],[TVA]],0) -> 204750.1 | Q25: 10238 | R25: =+Tableau330[[#This Row],[MONTANT TTC]]+Tableau330[[#This Row],[TIMBRE ]]+Tableau330[[#This Row],[AUTRES TAXES]] -> 214988.1 | S25: 214988 | T25: =+ROUND(Tableau330[[#This Row],[NET A PAYER]],0)-Tableau330[[#This Row],[MONTANT PAYE]] -> 0 | V25: =+Tableau330[[#This Row],[DELAI_PAIEMENT]]+Tableau330[[#This Row],[DATE ]] -> 45679
A26: 45679 | B26: =IF(ISBLANK(Tableau330[[#This Row],[DATE ]]),"",UPPER(PROPER(TEXT(Tableau330[[#This Row],[DATE ]],"mmmm yyyy")))) -> JANVIER 2025 | C26: NON-FN | D26: 2501/22/29 | E26: ISIS | H26: LOCATIONS BUREAU 02/25, 03/25 | M26: 600000 | N26: =+IF(Tableau330[[#This Row],[CODE TVA]]="",0,ROUND(Tableau330[[#This Row],[MONTANT HT]]*0.18*Tableau330[[#This Row],[PRORATA D]],1)) -> 0 | O26: =+IFERROR(Tableau330[[#This Row],[MONTANT HT]]+Tableau330[[#This Row],[TVA]],0) -> 600000 | R26: =+Tableau330[[#This Row],[MONTANT TTC]]+Tableau330[[#This Row],[TIMBRE ]]+Tableau330[[#This Row],[AUTRES TAXES]] -> 600000 | S26: 600000 | T26: =+ROUND(Tableau330[[#This Row],[NET A PAYER]],0)-Tableau330[[#This Row],[MONTANT PAYE]] -> 0 | V26: =+Tableau330[[#This Row],[DELAI_PAIEMENT]]+Tableau330[[#This Row],[DATE ]] -> 45679
A27: 45682 | B27: =IF(ISBLANK(Tableau330[[#This Row],[DATE ]]),"",UPPER(PROPER(TEXT(Tableau330[[#This Row],[DATE ]],"mmmm yyyy")))) -> JANVIER 2025 | C27: NON-FN | D27: 16653 | E27: SAWADOGO | H27: CABLE MOTOR | M27: 4000 | N27: =+IF(Tableau330[[#This Row],[CODE TVA]]="",0,ROUND(Tableau330[[#This Row],[MONTANT HT]]*0.18*Tableau330[[#This Row],[PRORATA D]],1)) -> 0 | O27: =+IFERROR(Tableau330[[#This Row],[MONTANT HT]]+Tableau330[[#This Row],[TVA]],0) -> 4000 | R27: =+Tableau330[[#This Row],[MONTANT TTC]]+Tableau330[[#This Row],[TIMBRE ]]+Tableau330[[#This Row],[AUTRES TAXES]] -> 4000 | S27: 4000 | T27: =+ROUND(Tableau330[[#This Row],[NET A PAYER]],0)-Tableau330[[#This Row],[MONTANT PAYE]] -> 0 | V27: =+Tableau330[[#This Row],[DELAI_PAIEMENT]]+Tableau330[[#This Row],[DATE ]] -> 45682
A28: 45685 | B28: =IF(ISBLANK(Tableau330[[#This Row],[DATE ]]),"",UPPER(PROPER(TEXT(Tableau330[[#This Row],[DATE ]],"mmmm yyyy")))) -> JANVIER 2025 | C28: FN | D28: 000359 | E28: MIRAN SARL | F28: 2300760 Z | G28: TEE | H28: BRIQUE CREUX 15*20*40 | M28: 300000 | N28: =+IF(Tableau330[[#This Row],[CODE TVA]]="",0,ROUND(Tableau330[[#This Row],[MONTANT HT]]*0.18*Tableau330[[#This Row],[PRORATA D]],1)) -> 0 | O28: =+IFERROR(Tableau330[[#This Row],[MONTANT HT]]+Tableau330[[#This Row],[TVA]],0) -> 300000 | R28: =+Tableau330[[#This Row],[MONTANT TTC]]+Tableau330[[#This Row],[TIMBRE ]]+Tableau330[[#This Row],[AUTRES TAXES]] -> 300000 | S28: 300000 | T28: =+ROUND(Tableau330[[#This Row],[NET A PAYER]],0)-Tableau330[[#This Row],[MONTANT PAYE]] -> 0 | V28: =+Tableau330[[#This Row],[DELAI_PAIEMENT]]+Tableau330[[#This Row],[DATE ]] -> 45685
A29: 45686 | B29: =IF(ISBLANK(Tableau330[[#This Row],[DATE ]]),"",UPPER(PROPER(TEXT(Tableau330[[#This Row],[DATE ]],"mmmm yyyy")))) -> JANVIER 2025 | C29: FN | D29: 035379 | E29: SPRIINT TECH | F29: 1106600 L | G29: RNI | H29: BATTERIE 12 VT | I29: TVA | J29: 1 | M29: -520551 | N29: =+IF(Tableau330[[#This Row],[CODE TVA]]="",0,ROUND(Tableau330[[#This Row],[MONTANT HT]]*0.18*Tableau330[[#This Row],[PRORATA D]],1)) -> -93699.2 | O29: =+IFERROR(Tableau330[[#This Row],[MONTANT HT]]+Tableau330[[#This Row],[TVA]],0) -> -614250.2 | Q29: -30713 | R29: =+Tableau330[[#This Row],[MONTANT TTC]]+Tableau330[[#This Row],[TIMBRE ]]+Tableau330[[#This Row],[AUTRES TAXES]] -> -644963.2 | S29: -644963.18 | T29: =+ROUND(Tableau330[[#This Row],[NET A PAYER]],0)-Tableau330[[#This Row],[MONTANT PAYE]] -> 0.18 | V29: =+Tableau330[[#This Row],[DELAI_PAIEMENT]]+Tableau330[[#This Row],[DATE ]] -> 45686
A30: 45686 | B30: =IF(ISBLANK(Tableau330[[#This Row],[DATE ]]),"",UPPER(PROPER(TEXT(Tableau330[[#This Row],[DATE ]],"mmmm yyyy")))) -> JANVIER 2025 | C30: FN | D30: 035381 | E30: SPRIINT TECH | F30: 1106600 L | G30: RNI | H30: BATTERIE 12 VT | I30: TVA | J30: 1 | M30: 521187 | N30: =+IF(Tableau330[[#This Row],[CODE TVA]]="",0,ROUND(Tableau330[[#This Row],[MONTANT HT]]*0.18*Tableau330[[#This Row],[PRORATA D]],1)) -> 93813.7 | O30: =+IFERROR(Tableau330[[#This Row],[MONTANT HT]]+Tableau330[[#This Row],[TVA]],0) -> 615000.7 | R30: =+Tableau330[[#This Row],[MONTANT TTC]]+Tableau330[[#This Row],[TIMBRE ]]+Tableau330[[#This Row],[AUTRES TAXES]] -> 615000.7 | S30: 615000.66 | T30: =+ROUND(Tableau330[[#This Row],[NET A PAYER]],0)-Tableau330[[#This Row],[MONTANT PAYE]] -> 0.34 | V30: =+Tableau330[[#This Row],[DELAI_PAIEMENT]]+Tableau330[[#This Row],[DATE ]] -> 45686
A31: 45686 | B31: =IF(ISBLANK(Tableau330[[#This Row],[DATE ]]),"",UPPER(PROPER(TEXT(Tableau330[[#This Row],[DATE ]],"mmmm yyyy")))) -> JANVIER 2025 | C31: FN | D31: 035382 | E31: SPRIINT TECH | H31: BATTERIE 12 VT | I31: TVA | J31: 1 | M31: 173729 | N31: =+IF(Tableau330[[#This Row],[CODE TVA]]="",0,ROUND(Tableau330[[#This Row],[MONTANT HT]]*0.18*Tableau330[[#This Row],[PRORATA D]],1)) -> 31271.2 | O31: =+IFERROR(Tableau330[[#This Row],[MONTANT HT]]+Tableau330[[#This Row],[TVA]],0) -> 205000.2 | R31: =+Tableau330[[#This Row],[MONTANT TTC]]+Tableau330[[#This Row],[TIMBRE ]]+Tableau330[[#This Row],[AUTRES TAXES]] -> 205000.2 | S31: 205000 | T31: =+ROUND(Tableau330[[#This Row],[NET A PAYER]],0)-Tableau330[[#This Row],[MONTANT PAYE]] -> 0 | V31: =+Tableau330[[#This Row],[DELAI_PAIEMENT]]+Tableau330[[#This Row],[DATE ]] -> 45686
A32: 45687 | B32: =IF(ISBLANK(Tableau330[[#This Row],[DATE ]]),"",UPPER(PROPER(TEXT(Tableau330[[#This Row],[DATE ]],"mmmm yyyy")))) -> JANVIER 2025 | C32: FN | D32: 035474 | E32: SPRIINT TECH | F32: 1106600 L | G32: RNI | H32: BATTERIE 12 VT | I32: TVA | J32: 1 | M32: 347034 | N32: =+IF(Tableau330[[#This Row],[CODE TVA]]="",0,ROUND(Tableau330[[#This Row],[MONTANT HT]]*0.18*Tableau330[[#This Row],[PRORATA D]],1)) -> 62466.1 | O32: =+IFERROR(Tableau330[[#This Row],[MONTANT HT]]+Tableau330[[#This Row],[TVA]],0) -> 409500.1 | P32: 500 | R32: =+Tableau330[[#This Row],[MONTANT TTC]]+Tableau330[[#This Row],[TIMBRE ]]+Tableau330[[#This Row],[AUTRES TAXES]] -> 410000.1 | S32: 410000 | T32: =+ROUND(Tableau330[[#This Row],[NET A PAYER]],0)-Tableau330[[#This Row],[MONTANT PAYE]] -> 0 | V32: =+Tableau330[[#This Row],[DELAI_PAIEMENT]]+Tableau330[[#This Row],[DATE ]] -> 45687
A33: 45688 | B33: =IF(ISBLANK(Tableau330[[#This Row],[DATE ]]),"",UPPER(PROPER(TEXT(Tableau330[[#This Row],[DATE ]],"mmmm yyyy")))) -> JANVIER 2025 | C33: FN | D33: 0017863 | E33: GUEPARD CIMENT | F33: 1700515 H | G33: RNI | H33: CIMENT GUEPARD CPJ 42,5 N | I33: TVA | J33: 1 | M33: 1322024 | N33: =+IF(Tableau330[[#This Row],[CODE TVA]]="",0,ROUND(Tableau330[[#This Row],[MONTANT HT]]*0.18*Tableau330[[#This Row],[PRORATA D]],1)) -> 237964.3 | O33: =+IFERROR(Tableau330[[#This Row],[MONTANT HT]]+Tableau330[[#This Row],[TVA]],0) -> 1559988.3 | R33: =+Tableau330[[#This Row],[MONTANT TTC]]+Tableau330[[#This Row],[TIMBRE ]]+Tableau330[[#This Row],[AUTRES TAXES]] -> 1559988.3 | S33: 1559988 | T33: =+ROUND(Tableau330[[#This Row],[NET A PAYER]],0)-Tableau330[[#This Row],[MONTANT PAYE]] -> 0 | V33: =+Tableau330[[#This Row],[DELAI_PAIEMENT]]+Tableau330[[#This Row],[DATE ]] -> 45688
A34: 45691 | B34: =IF(ISBLANK(Tableau330[[#This Row],[DATE ]]),"",UPPER(PROPER(TEXT(Tableau330[[#This Row],[DATE ]],"mmmm yyyy")))) -> FÉVRIER 2025 | C34: FN | D34: 00051 | E34: ANOH TECHNOLOGIES | F34: 2243084 G | G34: TEE | H34: 04 TELEPHONE SANS FILS VTECH | M34: 150000 | N34: =+IF(Tableau330[[#This Row],[CODE TVA]]="",0,ROUND(Tableau330[[#This Row],[MONTANT HT]]*0.18*Tableau330[[#This Row],[PRORATA D]],1)) -> 0 | O34: =+IFERROR(Tableau330[[#This Row],[MONTANT HT]]+Tableau330[[#This Row],[TVA]],0) -> 150000 | R34: =+Tableau330[[#This Row],[MONTANT TTC]]+Tableau330[[#This Row],[TIMBRE ]]+Tableau330[[#This Row],[AUTRES TAXES]] -> 150000 | S34: 150000 | T34: =+ROUND(Tableau330[[#This Row],[NET A PAYER]],0)-Tableau330[[#This Row],[MONTANT PAYE]] -> 0 | V34: =+Tableau330[[#This Row],[DELAI_PAIEMENT]]+Tableau330[[#This Row],[DATE ]] -> 45691
A35: 45691 | B35: =IF(ISBLANK(Tableau330[[#This Row],[DATE ]]),"",UPPER(PROPER(TEXT(Tableau330[[#This Row],[DATE ]],"mmmm yyyy")))) -> FÉVRIER 2025 | C35: FN | D35: 022727 | E35: PROSUMA | F35: 5011806 N | H35: PAPIER RAME, SUCRE MORCEAUX, LIPTON | I35: TVA | J35: 0.6637547 | M35: =9703+587 -> 10290 | N35: =+IF(Tableau330[[#This Row],[CODE TVA]]="",0,ROUND(Tableau330[[#This Row],[MONTANT HT]]*0.18*Tableau330[[#This Row],[PRORATA D]],1)) -> 1229.4 | O35: =+IFERROR(Tableau330[[#This Row],[MONTANT HT]]+Tableau330[[#This Row],[TVA]],0) -> 11519.4 | R35: =+Tableau330[[#This Row],[MONTANT TTC]]+Tableau330[[#This Row],[TIMBRE ]]+Tableau330[[#This Row],[AUTRES TAXES]] -> 11519.4 | S35: 11519 | T35: =+ROUND(Tableau330[[#This Row],[NET A PAYER]],0)-Tableau330[[#This Row],[MONTANT PAYE]] -> 0 | V35: =+Tableau330[[#This Row],[DELAI_PAIEMENT]]+Tableau330[[#This Row],[DATE ]] -> 45691
A36: 45691 | B36: =IF(ISBLANK(Tableau330[[#This Row],[DATE ]]),"",UPPER(PROPER(TEXT(Tableau330[[#This Row],[DATE ]],"mmmm yyyy")))) -> FÉVRIER 2025 | C36: FN | D36: 022769 | E36: PROSUMA | F36: 5011806 N | H36: EAU MINERALE | M36: 2500 | N36: =+IF(Tableau330[[#This Row],[CODE TVA]]="",0,ROUND(Tableau330[[#This Row],[MONTANT HT]]*0.18*Tableau330[[#This Row],[PRORATA D]],1)) -> 0 | O36: =+IFERROR(Tableau330[[#This Row],[MONTANT HT]]+Tableau330[[#This Row],[TVA]],0) -> 2500 | R36: =+Tableau330[[#This Row],[MONTANT TTC]]+Tableau330[[#This Row],[TIMBRE ]]+Tableau330[[#This Row],[AUTRES TAXES]] -> 2500 | S36: 2500 | T36: =+ROUND(Tableau330[[#This Row],[NET A PAYER]],0)-Tableau330[[#This Row],[MONTANT PAYE]] -> 0 | V36: =+Tableau330[[#This Row],[DELAI_PAIEMENT]]+Tableau330[[#This Row],[DATE ]] -> 45691
A37: 45694 | B37: =IF(ISBLANK(Tableau330[[#This Row],[DATE ]]),"",UPPER(PROPER(TEXT(Tableau330[[#This Row],[DATE ]],"mmmm yyyy")))) -> FÉVRIER 2025 | C37: FN | D37: 00406803 | E37: ESPERANCE TRANSPORT SUPER | F37: 2043577 U | H37: CLE CONTACTE POUR NIVELLEUSE | M37: 10000 | N37: =+IF(Tableau330[[#This Row],[CODE TVA]]="",0,ROUND(Tableau330[[#This Row],[MONTANT HT]]*0.18*Tableau330[[#This Row],[PRORATA D]],1)) -> 0 | O37: =+IFERROR(Tableau330[[#This Row],[MONTANT HT]]+Tableau330[[#This Row],[TVA]],0) -> 10000 | R37: =+Tableau330[[#This Row],[MONTANT TTC]]+Tableau330[[#This Row],[TIMBRE ]]+Tableau330[[#This Row],[AUTRES TAXES]] -> 10000 | S37: 10000 | T37: =+ROUND(Tableau330[[#This Row],[NET A PAYER]],0)-Tableau330[[#This Row],[MONTANT PAYE]] -> 0 | V37: =+Tableau330[[#This Row],[DELAI_PAIEMENT]]+Tableau330[[#This Row],[DATE ]] -> 45694
A38: 45695 | B38: =IF(ISBLANK(Tableau330[[#This Row],[DATE ]]),"",UPPER(PROPER(TEXT(Tableau330[[#This Row],[DATE ]],"mmmm yyyy")))) -> FÉVRIER 2025 | C38: FN | D38: 00406801 | E38: ESPERANCE TRANSPORT SUPER | F38: 2043577 U | H38: LOYER ET CAUTION MAISON CHAUFFEUR A KOUTO | M38: 50000 | N38: =+IF(Tableau330[[#This Row],[CODE TVA]]="",0,ROUND(Tableau330[[#This Row],[MONTANT HT]]*0.18*Tableau330[[#This Row],[PRORATA D]],1)) -> 0 | O38: =+IFERROR(Tableau330[[#This Row],[MONTANT HT]]+Tableau330[[#This Row],[TVA]],0) -> 50000 | R38: =+Tableau330[[#This Row],[MONTANT TTC]]+Tableau330[[#This Row],[TIMBRE ]]+Tableau330[[#This Row],[AUTRES TAXES]] -> 50000 | S38: 50000 | T38: =+ROUND(Tableau330[[#This Row],[NET A PAYER]],0)-Tableau330[[#This Row],[MONTANT PAYE]] -> 0 | V38: =+Tableau330[[#This Row],[DELAI_PAIEMENT]]+Tableau330[[#This Row],[DATE ]] -> 45695
A39: 45696 | B39: =IF(ISBLANK(Tableau330[[#This Row],[DATE ]]),"",UPPER(PROPER(TEXT(Tableau330[[#This Row],[DATE ]],"mmmm yyyy")))) -> FÉVRIER 2025 | C39: FN | D39: 022916 | E39: PROSUMA | F39: 5011806 N | H39: DIVERS ARTICLES | I39: TVA | J39: 1 | M39: 68008 | N39: =+IF(Tableau330[[#This Row],[CODE TVA]]="",0,ROUND(Tableau330[[#This Row],[MONTANT HT]]*0.18*Tableau330[[#This Row],[PRORATA D]],1)) -> 12241.4 | O39: =+IFERROR(Tableau330[[#This Row],[MONTANT HT]]+Tableau330[[#This Row],[TVA]],0) -> 80249.4 | P39: 100 | R39: =+Tableau330[[#This Row],[MONTANT TTC]]+Tableau330[[#This Row],[TIMBRE ]]+Tableau330[[#This Row],[AUTRES TAXES]] -> 80349.4 | S39: 80349 | T39: =+ROUND(Tableau330[[#This Row],[NET A PAYER]],0)-Tableau330[[#This Row],[MONTANT PAYE]] -> 0 | V39: =+Tableau330[[#This Row],[DELAI_PAIEMENT]]+Tableau330[[#This Row],[DATE ]] -> 45696
A40: 45697 | B40: =IF(ISBLANK(Tableau330[[#This Row],[DATE ]]),"",UPPER(PROPER(TEXT(Tableau330[[#This Row],[DATE ]],"mmmm yyyy")))) -> FÉVRIER 2025 | C40: FN | D40: 0356788 | E40: AUTO ROY | F40: 0814617 Y | G40: RME | H40: PNEU 385/65 R22,5 | M40: 300000 | N40: =+IF(Tableau330[[#This Row],[CODE TVA]]="",0,ROUND(Tableau330[[#This Row],[MONTANT HT]]*0.18*Tableau330[[#This Row],[PRORATA D]],1)) -> 0 | O40: =+IFERROR(Tableau330[[#This Row],[MONTANT HT]]+Tableau330[[#This Row],[TVA]],0) -> 300000 | R40: =+Tableau330[[#This Row],[MONTANT TTC]]+Tableau330[[#This Row],[TIMBRE ]]+Tableau330[[#This Row],[AUTRES TAXES]] -> 300000 | S40: 300000 | T40: =+ROUND(Tableau330[[#This Row],[NET A PAYER]],0)-Tableau330[[#This Row],[MONTANT PAYE]] -> 0 | V40: =+Tableau330[[#This Row],[DELAI_PAIEMENT]]+Tableau330[[#This Row],[DATE ]] -> 45697
...

Sheet SOUS_TRAITANTS
C1: Montant Initial de Contrat | F1: Compte de Résultat | G1: Tableau des Flux de Trésorerie | H1: Bilan - Passif | I1: Engagement Restant (Non Facturé)
A4: N° Contrat | B4: Nom Sous-Traitant | C4: Montant Total Contrat | D4: Date Début | E4: Date Fin | F4: Montant Consommé (période) | G4: Paiements Effectués | H4: Solde Facturé Non Payé | I4: Solde Restant | J4: Observations
A5: ST-001 | B5: Entreprise A | C5: 5000000 | D5: 01/01/2025 | E5: 31/12/2025 | F5: 2000000 | G5: 1000000 | H5: =+F5-G5 -> 1000000 | I5: 4000000 | J5: Facture attendue
A6: ST-002 | B6: Entreprise B | C6: 3000000 | D6: 15/02/2025 | E6: 30/06/2025 | F6: 1500000 | G6: 1000000 | H6: =+F6-G6 -> 500000 | I6: 1500000 | J6: Avancement 50%
A7: ST-003 | B7: Entreprise C | C7: 7000000 | D7: 01/03/2025 | E7: 31/12/2025 | F7: 3000000 | G7: 2500000 | H7: =+F7-G7 -> 500000 | I7: 4500000 | J7: Contrat en cours
B8: TOTAL | C8: =SUM(C5:C7) -> 15000000 | F8: =SUM(F5:F7) -> 6500000 | G8: =SUM(G5:G7) -> 4500000 | H8: =SUM(H5:H7) -> 2000000 | I8: =SUM(I5:I7) -> 10000000

Sheet BASE FRAIS GENERAUX (2)
A2: N° | B2: ENTITE | C2: SOUS ENTITE | D2: FOURNISSEUR | E2: CONTRAT N° | F2: TYPE DE CONTRAT | G2: NATURE DE CONTRAT | H2: BIEN CONCERNE | I2: N° FICHE/DOSSIER | J2: POSTE BUDGETAIRE | K2: MONTANT HT | L2: TAUX TVA | M2: TVA | N2: MONTANT TTC | O2: MONTANT PERIODIQUE | P2: DUREE | Q2: UNITE_DUREE | R2: DATE DE DEBUT | S2: JOUR DE PRELEVEMENT | T2: MOIS COUVERTS PAR VERSEMENT INITIAL | U2: PREMIERE DATE ECHEANCE | V2: PROCHAINE ÉCHÉANCE | W2: PÉRIODICITÉ | X2: DATE DERNIER PAIEMENT | Y2: DATE PROCHAIN PRELEVEMENT | Z2: STATUT (PAYÉ/IMPAYÉ) | AA2: NBRE PRELEVEMENTS REALISES | AB2: NBRE PRELEVEMENTS IMPAYES | AC2: PROCHAINE ECHEANCE | AD2: NBRE DE FACTURES RECUS | AE2: MODE DE PAIEMENT | AF2: RECONDUCTION | AG2: COMMENTAIRE
A3: =+COUNTIF($J$2:J3,"="&Tableau529[[#This Row],[POSTE BUDGETAIRE]]) -> 1 | B3: SIM GROUP | D3: OUMAR | F3: ABONNEMENT | G3: CONTRAT DE BAIL | J3: LOCATION | K3: 700000 | M3: =+Tableau529[[#This Row],[MONTANT HT]]*Tableau529[[#This Row],[TAUX TVA]] -> 0 | N3: =+Tableau529[[#This Row],[MONTANT HT]]+Tableau529[[#This Row],[TVA]] -> 700000 | O3: 700000 | Q3: MOIS | S3: 5 | V3: =IF(Tableau529[[#This Row],[PREMIERE DATE ECHEANCE]]="","",EDATE(Tableau529[[#This Row],[PREMIERE DATE ECHEANCE]],1)+COUNTIFS(Tableau529[[#This Row],[STATUT (PAYÉ/IMPAYÉ)]],"Impayé")*CHOOSE(MATCH(Tableau529[[#This Row],[PÉRIODICITÉ]],{"hebdomadaire";"quinzaine";"mensuelle";"bimestrielle";"trimestrielle";"semestrielle";"annuelle"},0),7,15,30,60,90,180,365)) | W3: MENSUELLE | X3: 45839 | Y3: =IF(Tableau529[[#This Row],[PÉRIODICITÉ]]="mensuelle",DATE(YEAR(Tableau529[[#This Row],[DATE DE DEBUT]])+INT((MONTH(Tableau529[[#This Row],[DATE DE DEBUT]])+Tableau529[[#This Row],[MOIS COUVERTS PAR VERSEMENT INITIAL]]+Tableau529[[#This Row],[NBRE PRELEVEMENTS REALISES]]-Tableau529[[#This Row],[NBRE PRELEVEMENTS IMPAYES]]-1)/12), MOD(MONTH(Tableau529[[#This Row],[DATE DE DEBUT]])+Tableau529[[#This Row],[MOIS COUVERTS PAR VERSEMENT INITIAL]]+Tableau529[[#This Row],[NBRE PRELEVEMENTS REALISES]]-Tableau529[[#This Row],[NBRE PRELEVEMENTS IMPAYES]]-1,12)+1,Tableau529[[#This Row],[JOUR DE PRELEVEMENT]]), IF(Tableau529[[#This Row],[PÉRIODICITÉ]]="bimestrielle",DATE(YEAR(Tableau529[[#This Row],[DATE DE DEBUT]])+INT((MONTH(Tableau529[[#This Row],[DATE DE DEBUT]])+(Tableau529[[#This Row],[MOIS COUVERTS PAR VERSEMENT INITIAL]]+Tableau529[[#This Row],[NBRE PRELEVEMENTS REALISES]]-Tableau529[[#This Row],[NBRE PRELEVEMENTS IMPAYES]])*2-1)/12), MOD(MONTH(Tableau529[[#This Row],[DATE DE DEBUT]])+(Tableau529[[#This Row],[MOIS COUVERTS PAR VERSEMENT INITIAL]]+Tableau529[[#This Row],[NBRE PRELEVEMENTS REALISES]]-Tableau529[[#This Row],[NBRE PRELEVEMENTS IMPAYES]])*2-1,12)+1,Tableau529[[#This Row],[JOUR DE PRELEVEMENT]]), "")) -> #VALUE! | Z3: =IFERROR( IF(Tableau529[[#This Row],[NBRE PRELEVEMENTS IMPAYES]]<=0,"PAYÉ", IF(Tableau529[[#This Row],[NBRE PRELEVEMENTS REALISES]]>0,"EN RETARD","IMPAYÉ")),"") -> EN RETARD | AA3: =IF(OR(Tableau529[[#This Row],[PREMIERE DATE ECHEANCE]]="",Tableau529[[#This Row],[PÉRIODICITÉ]]=""),"", MAX(0, INT((TODAY() - Tableau529[[#This Row],[PREMIERE DATE ECHEANCE]]) / CHOOSE(MATCH(Tableau529[[#This Row],[PÉRIODICITÉ]], {"HEBDOMADAIRE";"QUINZAINE";"MENSUELLE";"BIMESTRIELLE";"TRIMESTRIELLE";"SEMESTRIELLE";"ANNUELLE"}, 0), 7,15,30,60,90,180,365 ) ) -Tableau529[[#This Row],[MOIS COUVERTS PAR VERSEMENT INITIAL]] ) ) | AB3: =IF(OR(Tableau529[[#This Row],[PREMIERE DATE ECHEANCE]]="",Tableau529[[#This Row],[PÉRIODICITÉ]]=""),"", MAX(0, INT((TODAY() - Tableau529[[#This Row],[PREMIERE DATE ECHEANCE]]) / CHOOSE(MATCH(Tableau529[[#This Row],[PÉRIODICITÉ]], {"HEBDOMADAIRE";"QUINZAINE";"MENSUELLE";"BIMESTRIELLE";"TRIMESTRIELLE";"SEMESTRIELLE";"ANNUELLE"}, 0), 7,15,30,60,90,180,365) ) -Tableau529[[#This Row],[MOIS COUVERTS PAR VERSEMENT INITIAL]] -Tableau529[[#This Row],[NBRE PRELEVEMENTS REALISES]] ) ) | AC3: =IF(W3="mensuelle",DATE(YEAR(X3),MONTH(X3)+1,DAY(X3)), IF(W3="hebdomadaire",X3+7, IF(W3="quinzaine",X3+14, IF(W3="trimestrielle",DATE(YEAR(X3),MONTH(X3)+3,DAY(X3)), IF(W3="semestrielle",DATE(YEAR(X3),MONTH(X3)+6,DAY(X3)), IF(W3="annuelle",DATE(YEAR(X3),MONTH(X3)+12,DAY(X3)), "")))))) -> 45870 | AE3: RECURENT
A4: =+COUNTIF($J$2:J4,"="&Tableau529[[#This Row],[POSTE BUDGETAIRE]]) -> 1 | B4: TEXTIPRINT | D4: TIMAOC SDI | E4: CV0023/25 | F4: PAIEMENT ECHELONNE | G4: VENTE AVEC PAIEMENT ECHELONNE | H4: PRESSE NUMERIQUE-KONICA | J4: IMMOBILISATION | K4: 17796610 | L4: 0.18 | M4: =+Tableau529[[#This Row],[MONTANT HT]]*Tableau529[[#This Row],[TAUX TVA]] -> 3203389.8 | N4: =+Tableau529[[#This Row],[MONTANT HT]]+Tableau529[[#This Row],[TVA]] -> 21000000 | O4: 1000000 | P4: 20 | Q4: MOIS | R4: 45581 | S4: 10 | T4: 3 | U4: =IFERROR(EDATE( DATE(YEAR(Tableau529[[#This Row],[DATE DE DEBUT]]), MONTH(Tableau529[[#This Row],[DATE DE DEBUT]]), Tableau529[[#This Row],[JOUR DE PRELEVEMENT]]), Tableau529[[#This Row],[MOIS COUVERTS PAR VERSEMENT INITIAL]] ),"") -> 45667 | V4: =IF(Tableau529[[#This Row],[PREMIERE DATE ECHEANCE]]="","",EDATE(Tableau529[[#This Row],[PREMIERE DATE ECHEANCE]],1)+COUNTIFS(Tableau529[[#This Row],[STATUT (PAYÉ/IMPAYÉ)]],"Impayé")*CHOOSE(MATCH(Tableau529[[#This Row],[PÉRIODICITÉ]],{"hebdomadaire";"quinzaine";"mensuelle";"bimestrielle";"trimestrielle";"semestrielle";"annuelle"},0),7,15,30,60,90,180,365)) -> 45698 | W4: MENSUELLE | X4: 45581 | Y4: =IF(Tableau529[[#This Row],[PÉRIODICITÉ]]="mensuelle",DATE(YEAR(Tableau529[[#This Row],[DATE DE DEBUT]])+INT((MONTH(Tableau529[[#This Row],[DATE DE DEBUT]])+Tableau529[[#This Row],[MOIS COUVERTS PAR VERSEMENT INITIAL]]+Tableau529[[#This Row],[NBRE PRELEVEMENTS REALISES]]-Tableau529[[#This Row],[NBRE PRELEVEMENTS IMPAYES]]-1)/12), MOD(MONTH(Tableau529[[#This Row],[DATE DE DEBUT]])+Tableau529[[#This Row],[MOIS COUVERTS PAR VERSEMENT INITIAL]]+Tableau529[[#This Row],[NBRE PRELEVEMENTS REALISES]]-Tableau529[[#This Row],[NBRE PRELEVEMENTS IMPAYES]]-1,12)+1,Tableau529[[#This Row],[JOUR DE PRELEVEMENT]]), IF(Tableau529[[#This Row],[PÉRIODICITÉ]]="bimestrielle",DATE(YEAR(Tableau529[[#This Row],[DATE DE DEBUT]])+INT((MONTH(Tableau529[[#This Row],[DATE DE DEBUT]])+(Tableau529[[#This Row],[MOIS COUVERTS PAR VERSEMENT INITIAL]]+Tableau529[[#This Row],[NBRE PRELEVEMENTS REALISES]]-Tableau529[[#This Row],[NBRE PRELEVEMENTS IMPAYES]])*2-1)/12), MOD(MONTH(Tableau529[[#This Row],[DATE DE DEBUT]])+(Tableau529[[#This Row],[MOIS COUVERTS PAR VERSEMENT INITIAL]]+Tableau529[[#This Row],[NBRE PRELEVEMENTS REALISES]]-Tableau529[[#This Row],[NBRE PRELEVEMENTS IMPAYES]])*2-1,12)+1,Tableau529[[#This Row],[JOUR DE PRELEVEMENT]]), "")) -> 46001 | Z4: =IFERROR( IF(Tableau529[[#This Row],[NBRE PRELEVEMENTS IMPAYES]]<=0,"PAYÉ", IF(Tableau529[[#This Row],[NBRE PRELEVEMENTS REALISES]]>0,"EN RETARD","IMPAYÉ")),"") -> PAYÉ | AA4: =IF(OR(Tableau529[[#This Row],[PREMIERE DATE ECHEANCE]]="",Tableau529[[#This Row],[PÉRIODICITÉ]]=""),"", MAX(0, INT((TODAY() - Tableau529[[#This Row],[PREMIERE DATE ECHEANCE]]) / CHOOSE(MATCH(Tableau529[[#This Row],[PÉRIODICITÉ]], {"HEBDOMADAIRE";"QUINZAINE";"MENSUELLE";"BIMESTRIELLE";"TRIMESTRIELLE";"SEMESTRIELLE";"ANNUELLE"}, 0), 7,15,30,60,90,180,365 ) ) -Tableau529[[#This Row],[MOIS COUVERTS PAR VERSEMENT INITIAL]] ) ) -> 11 | AB4: =IF(OR(Tableau529[[#This Row],[PREMIERE DATE ECHEANCE]]="",Tableau529[[#This Row],[PÉRIODICITÉ]]=""),"", MAX(0, INT((TODAY() - Tableau529[[#This Row],[PREMIERE DATE ECHEANCE]]) / CHOOSE(MATCH(Tableau529[[#This Row],[PÉRIODICITÉ]], {"HEBDOMADAIRE";"QUINZAINE";"MENSUELLE";"BIMESTRIELLE";"TRIMESTRIELLE";"SEMESTRIELLE";"ANNUELLE"}, 0), 7,15,30,60,90,180,365) ) -Tableau529[[#This Row],[MOIS COUVERTS PAR VERSEMENT INITIAL]] -Tableau529[[#This Row],[NBRE PRELEVEMENTS REALISES]] ) ) -> 0 | AC4: =IF(W4="mensuelle",DATE(YEAR(X4),MONTH(X4)+1,DAY(X4)), IF(W4="hebdomadaire",X4+7, IF(W4="quinzaine",X4+14, IF(W4="trimestrielle",DATE(YEAR(X4),MONTH(X4)+3,DAY(X4)), IF(W4="semestrielle",DATE(YEAR(X4),MONTH(X4)+6,DAY(X4)), IF(W4="annuelle",DATE(YEAR(X4),MONTH(X4)+12,DAY(X4)), "")))))) -> 45612 | AE4: ECHEANCIER | AF4: NON
AA8: =IF(TYPE_DE_CONTRAT="ABONNEMENT",MAX(0,X2-Z2),MAX(0,MIN(DUREE,X2)-Z2)) -> #NAME?

Sheet NOTE
B2: Procédure manuelle pour compléter les informations
B3: 1. Collectez les factures liées :
B4: Demandez aux fournisseurs de fournir les factures pour chaque fiche de dépense validée.
B5: 2. Vérifiez les montants et les conditions :
B6: Assurez-vous que les montants sur la facture correspondent à ceux engagés.
B7: Si une différence est détectée, mettez à jour le montant dans la fiche.
B8: 3. Mettez à jour le tableau :
B9: Ajoutez les informations de la facture (fournisseur, numéro de facture, échéance réelle).
B10: Changez le statut à "Dette fournisseur".
B12: Transition visuelle pour le suivi
B13: Utilisez une mise en forme conditionnelle pour identifier les fiches prêtes à être converties :
B14: Rouge : Engagement sans facture.
... B38: Une facture peut passer successivement par ces statuts :
B40: Étape | C40: Statut à indiquer sur la facture
B41: 1 | C41: En attente de paiement
B42: 2 | C42: Retenue pour paiement suivant (si applicable)
B43: 3 | C43: Payée le [date]
B46: 3. ✍️ Mise à jour des statuts à la main
B48: ✅ Recommandations :
B50: Barrer proprement l'ancien statut à l’encre (ne pas utiliser de correcteur blanc).
B52: Écrire clairement le nouveau statut juste à côté ou en dessous.
B54: Utiliser un stylo bleu ou noir pour la lisibilité.
B56: Ajouter vos initiales et la date de mise à jour, surtout si plusieurs personnes manipulent la facture.
B58: 📌 Exemple sur une facture :
B60: swift
B61: CopierModifier
B62: ~~En attente de paiement~~
B63: Retenue pour paiement fin juillet – MA – 12/07/2025
B65: puis :
... B76: 📁 Classement par statut avec intercalaires ou chemises de couleur :
B78: Couleur / Section | C78: Contenu
B79: 🔵 Bleu : À traiter | C79: Factures "en attente de paiement"
B80: 🟡 Jaune : À programmer | C80: Factures "retenues pour paiement suivant"
B81: 🟢 Vert : Payées | C81: Factures "réglées", avec mention de la date
B83: ✅ Astuces :
B85: Classer par date d’échéance à l’intérieur de chaque section.
B87: Joindre si besoin une fiche de suivi manuelle à chaque facture.

Sheet PLAN COMPTABLE

Sheet EVALUATION DETTES
A1: ENTITÉ | B1: DATE | C1: TYPE D’INFORMATION | D1: MONTANT (FCFA) | E1: DESCRIPTION | F1: DEMANDEUR | G1: DELAI | H1: ÉCHÉANCE | I1: STATUT
A2: ROYAL LT | B2: 45609 | C2: ENGAGEMENT | D2: 218300 | E2: EDITION FACTURES NORMALISEES A4 RECTO SIMPLE | G2: 0 | H2: =+Tableau15[[#This Row],[DATE]]+Tableau15[[#This Row],[DELAI]] -> 45609 | I2: EN ATTENTE DE PAIEMENT
A3: ROYAL LT | B3: 45664 | C3: ENGAGEMENT | D3: 250000 | E3: REPARATION CAMION A BOUAKE-PERIODE DECEMBRE 2024 | G3: 0 | H3: =+Tableau15[[#This Row],[DATE]]+Tableau15[[#This Row],[DELAI]] -> 45664 | I3: EN ATTENTE DE PAIEMENT
A4: SIGIB | B4: 45609 | C4: ENGAGEMENT | D4: 218300 | E4: EDITION FACTURES NORMALISEES A4 RECTO SIMPLE | G4: 0 | H4: =+Tableau15[[#This Row],[DATE]]+Tableau15[[#This Row],[DELAI]] -> 45609 | I4: EN ATTENTE DE PAIEMENT
A5: SIM BETON | B5: 45650 | C5: DETTES FOURNISSEURS | D5: 2550000 | E5: LOYER SITE DE PRODUCTION ABJ-4,5 MOIS_OPTIGESTION | G5: 0 | H5: =+Tableau15[[#This Row],[DATE]]+Tableau15[[#This Row],[DELAI]] -> 45650 | I5: NON REGLE
A6: SIM BETON | B6: 45665 | C6: ENGAGEMENT | D6: 82600 | E6: CARNET BL 3 FEUILLETS | G6: 0 | H6: =+Tableau15[[#This Row],[DATE]]+Tableau15[[#This Row],[DELAI]] -> 45665 | I6: EN ATTENTE DE PAIEMENT
A7: SIM BETON | B7: 45670 | C7: ENGAGEMENT | D7: 111000 | E7: FRAIS DE PRODUCTION SEMAINE DU 14 AU 19/01/2025-SITE BKE | G7: 0 | H7: =+Tableau15[[#This Row],[DATE]]+Tableau15[[#This Row],[DELAI]] -> 45670 | I7: EN ATTENTE DE PAIEMENT
A8: SIM BETON | B8: 45670 | C8: ENGAGEMENT | D8: 221375 | E8: FRAIS DE PRODUCTION SEMAINE DU 14 AU 19/01/2025-SITE ABJ | G8: 0 | H8: =+Tableau15[[#This Row],[DATE]]+Tableau15[[#This Row],[DELAI]] -> 45670 | I8: EN ATTENTE DE PAIEMENT
A9: SIM BETON | B9: 45670 | C9: ENGAGEMENT | D9: 93500 | E9: FRAIS DE PRODUCTION SEMAINE DU 14 AU 19/01/2025-SITE MAN | G9: 0 | H9: =+Tableau15[[#This Row],[DATE]]+Tableau15[[#This Row],[DELAI]] -> 45670 | I9: EN ATTENTE DE PAIEMENT
A10: SIM GROUP | B10: 45653 | C10: DETTES FOURNISSEURS | D10: =100000+473000+123000+42000 -> 738000 | E10: FACTURES GARAGE TS & FILS (04) | G10: 0 | H10: =+Tableau15[[#This Row],[DATE]]+Tableau15[[#This Row],[DELAI]] -> 45653 | I10: EN ATTENTE DE PAIEMENT
A11: SIM GROUP | B11: 45668 | C11: ENGAGEMENT | D11: 450000 | E11: CAUTION AGENT DE SECURITE ET FRAIS CREATION SIM BETON | G11: 0 | H11: =+Tableau15[[#This Row],[DATE]]+Tableau15[[#This Row],[DELAI]] -> 45668 | I11: EN ATTENTE DE PAIEMENT
A12: SINERGIE RESEAU | B12: 45941 | C12: ENGAGEMENT | D12: 200000 | E12: PRESTATION CIC-SAN PEDRO | G12: 0 | H12: =+Tableau15[[#This Row],[DATE]]+Tableau15[[#This Row],[DELAI]] -> 45941 | I12: EN ATTENTE DE PAIEMENT
A13: SINERGIE RESEAU | B13: 45466 | C13: FRAIS PROFESSIONNELS | D13: 43935 | E13: CARBURANT ET ACHAT MECHES-KOUAME SYLVIE | G13: 0 | H13: =+Tableau15[[#This Row],[DATE]]+Tableau15[[#This Row],[DELAI]] -> 45466 | I13: EN ATTENTE DE PAIEMENT
A14: SINERGIE RESEAU | B14: 45482 | C14: FRAIS PROFESSIONNELS | D14: 16500 | E14: CARBURANT ET ACHAT MECHES-KOUAME SYLVIE | G14: 0 | H14: =+Tableau15[[#This Row],[DATE]]+Tableau15[[#This Row],[DELAI]] -> 45482 | I14: EN ATTENTE DE PAIEMENT
A15: SINERGIE RESEAU | B15: 45486 | C15: FRAIS PROFESSIONNELS | D15: 16500 | E15: MO JOURNALIERE POUR PRESTATION-KOUAME SYLVIE | G15: 0 | H15: =+Tableau15[[#This Row],[DATE]]+Tableau15[[#This Row],[DELAI]] -> 45486 | I15: EN ATTENTE DE PAIEMENT
A16: SINERGIE RESEAU | B16: 45487 | C16: FRAIS PROFESSIONNELS | D16: 8080 | E16: FOUILLES ALEX-KOUAME SYLVIE | G16: 0 | H16: =+Tableau15[[#This Row],[DATE]]+Tableau15[[#This Row],[DELAI]] -> 45487 | I16: EN ATTENTE DE PAIEMENT
A17: SINERGIE RESEAU | B17: 45488 | C17: FRAIS PROFESSIONNELS | D17: 33000 | E17: PRESTATION INFRA DU 15/7/24-KOUAME SYLVIE | G17: 0 | H17: =+Tableau15[[#This Row],[DATE]]+Tableau15[[#This Row],[DELAI]] -> 45488 | I17: EN ATTENTE DE PAIEMENT
A18: SINERGIE RESEAU | B18: 45573 | C18: FRAIS PROFESSIONNELS | D18: 3500 | E18: TRANSPORT POUR LE RETRAIT DU BC N° 4 CIC-TIKANA | G18: 0 | H18: =+Tableau15[[#This Row],[DATE]]+Tableau15[[#This Row],[DELAI]] -> 45573 | I18: NON REMBOURSE
A19: SINERGIE RESEAU | B19: 45580 | C19: DETTES SOCIALES | D19: 458927 | E19: COTISATION CNPS 3T 2024 | G19: 0 | H19: =+Tableau15[[#This Row],[DATE]]+Tableau15[[#This Row],[DELAI]] -> 45580 | I19: EN ATTENTE DE PAIEMENT
A20: SINERGIE RESEAU | B20: 45581 | C20: FRAIS PROFESSIONNELS | D20: 40000 | E20: ACHAT OUTIL SLITTER-TIKANA | G20: 0 | H20: =+Tableau15[[#This Row],[DATE]]+Tableau15[[#This Row],[DELAI]] -> 45581 | I20: NON REMBOURSE
A21: SINERGIE RESEAU | B21: 45586 | C21: FRAIS PROFESSIONNELS | D21: 15000 | E21: FRAIS DE DEPLACEMENT YANGO CARGO ALLER-TIKANA | G21: 0 | H21: =+Tableau15[[#This Row],[DATE]]+Tableau15[[#This Row],[DELAI]] -> 45586 | I21: NON REMBOURSE
A22: SINERGIE RESEAU | B22: 45598 | C22: ENGAGEMENT | D22: 52500 | E22: FOUILLES IMPREVU | G22: 0 | H22: =+Tableau15[[#This Row],[DATE]]+Tableau15[[#This Row],[DELAI]] -> 45598 | I22: EN ATTENTE DE PAIEMENT
... A37: SINERGIE RESEAU | B37: 45670 | C37: ENGAGEMENT | D37: 525200 | E37: PRESTATION ELECTRICITE-CIC MAN | G37: 0 | H37: =+Tableau15[[#This Row],[DATE]]+Tableau15[[#This Row],[DELAI]] -> 45670 | I37: EN ATTENTE DE PAIEMENT
H38: =+Tableau15[[#This Row],[DATE]]+Tableau15[[#This Row],[DELAI]] -> 0
H39: =+Tableau15[[#This Row],[DATE]]+Tableau15[[#This Row],[DELAI]] -> 0
H40: =+Tableau15[[#This Row],[DATE]]+Tableau15[[#This Row],[DELAI]] -> 0
H41: =+Tableau15[[#This Row],[DATE]]+Tableau15[[#This Row],[DELAI]] -> 0
H42: =+Tableau15[[#This Row],[DATE]]+Tableau15[[#This Row],[DELAI]] -> 0
H43: =+Tableau15[[#This Row],[DATE]]+Tableau15[[#This Row],[DELAI]] -> 0
A44: Total | D44: =SUBTOTAL(109,Tableau15[MONTANT (FCFA)]) -> 10948542 | I44: =SUBTOTAL(103,Tableau15[STATUT]) -> 36

Sheet ECHEANCIER
A1: ENTITÉ | B1: FOURNISSEUR | C1: CONTACT | D1: TYPE DE DETTES | E1: TYPE DE DÉPENSE | F1: DETAIL DE LA DEPENSE | G1: NUMÉRO DE FACTURE | H1: DATE DE FACTURATION | I1: MONTANT TTC | J1: ÉCHÉANCE | K1: MONTANT ÉCHU | L1: MONTANT NON ÉCHU | M1: STATUT (PAYÉ / EN ATTENTE) | N1: DATE DE PAIEMENT
A2: SINERGIE RESEAU | B2: TRAORE MAMADOU P/C HAMED LOCATION | D2: HORS GROUPE | E2: ACHATS D 'EXPLOITATION | F2: LOCATIONS GRUE | I2: 1000000 | M2: EN ATTENTE
A3: SINERGIE RESEAU | B3: FARAH ET FRERES | D3: HORS GROUPE | E3: ACHATS D 'EXPLOITATION | F3: ACQUISITION DE 3 VEHICULES | I3: 5050000 | M3: EN ATTENTE
A4: SINERGIE RESEAU | B4: SANOGO | C4: 0103404600 | D4: HORS GROUPE | E4: ACHATS D 'EXPLOITATION | F4: GROUPE ELECTROGÈNE-LOCATION DE MARTEAUX PIQUEUR | I4: 350000 | M4: EN ATTENTE
A5: SINERGIE RESEAU | B5: KOUAME SYLVIE | D5: HORS GROUPE | E5: ACHATS D 'EXPLOITATION | F5: MATERIEL INFRA | I5: 1618400 | M5: EN ATTENTE
A6: SINERGIE RESEAU | B6: ENTREPRISE SAVANE | C6: 0700612128 | D6: HORS GROUPE | E6: ACHATS D 'EXPLOITATION | F6: LOCATION DE VEHICULE POUR ACTION INFRA | I6: 610000 | M6: EN ATTENTE
A7: SINERGIE RESEAU | B7: FOUILLES | D7: HORS GROUPE | E7: ACHATS D 'EXPLOITATION | F7: FOUILLES BETON (AVRIL, MAI, JUIN, JUILLET ET AOUT) 2024 | I7: 1014000 | M7: EN ATTENTE
A8: SINERGIE RESEAU | B8: FOUILLES | D8: HORS GROUPE | E8: ACHATS D 'EXPLOITATION | F8: FOUILLES METALLIQUES ( AVRIL, MAI, JUIN ET JUILLET) 2024 | I8: 1215500 | M8: EN ATTENTE
A9: SINERGIE RESEAU | B9: LOCATION ABOBO | D9: HORS GROUPE | E9: ACHATS D 'EXPLOITATION | F9: LOCATION DE BACHÉ | I9: 80000 | M9: EN ATTENTE
A10: SINERGIE RESEAU | B10: TEFR | D10: HORS GROUPE | E10: ACHATS D 'EXPLOITATION | F10: EQUIPE DE TIRAGE ABOBO / INNOV | I10: 147510 | M10: EN ATTENTE
A11: SINERGIE RESEAU | B11: ROYAL LOGISTIQUES | D11: INTRA-GROUPE | E11: ACHATS D 'EXPLOITATION | F11: LOCATIONS GRUE | I11: 10640000 | M11: EN ATTENTE
A12: SINERGIE RESEAU | B12: TEXTIPRINT | D12: INTRA-GROUPE | E12: ACHATS D 'EXPLOITATION | F12: PRÊT A TEXTPRINT | I12: 3136800 | M12: EN ATTENTE
A13: SINERGIE RESEAU | B13: SIGIB | D13: INTRA-GROUPE | E13: ACHATS D 'EXPLOITATION | F13: PRÊT A SIGIB | I13: 500000 | M13: EN ATTENTE
A14: SIGIB | B14: PERSONNEL | D14: INTRA-GROUPE | E14: FRAIS GENERAUX | F14: SALAIRE AOUT A OCTOBRE 2024 | H14: 45505 | I14: 1860000 | J14: 45596 | M14: EN ATTENTE
A15: SIGIB | B15: COULIBALY | D15: HORS GROUPE | E15: ACHATS D 'EXPLOITATION | F15: LOCATION DE LOGICIEL MAI A JUILLET 2024 | H15: 45413 | I15: 100000 | J15: 45504 | M15: EN ATTENTE
A16: SIGIB | B16: N'GORAN ULRICHE | C16: 0757288788 | D16: HORS GROUPE | E16: ACHATS D 'EXPLOITATION | F16: CREATION DE LOGO ET AFFICHE | H16: 45474 | I16: 25000 | J16: 45504 | M16: EN ATTENTE
A17: SIGIB | B17: KOFFI GERARD | C17: 0768054715 | D17: HORS GROUPE | E17: ACHATS D 'EXPLOITATION | F17: FOUILLES | H17: 45474 | I17: 70000 | J17: 45504 | M17: EN ATTENTE
A18: ROYAL LT | B18: KOUYATE | D18: HORS GROUPE | E18: ACHATS D 'EXPLOITATION | F18: MECANIQUE HYDROLIQUE GRUE ET PIECES DETACHEES | H18: 45222 | I18: 560000 | J18: 45222 | M18: EN ATTENTE
A19: ROYAL LT | B19: ADIMI | D19: HORS GROUPE | E19: ACHATS D 'EXPLOITATION | F19: AQUISITION D'UN TRACTEUR ROUTIER COULEUR VERTE | H19: 45199 | I19: 5000000 | J19: 45199 | M19: EN ATTENTE
A20: ROYAL LT | B20: KAMATE | D20: HORS GROUPE | E20: ACHATS D 'EXPLOITATION | F20: MECANIQUE DE CAMION BLEU-DEPANNAGE | H20: 45352 | I20: 90000 | J20: 45352 | M20: EN ATTENTE
A21: ROYAL LT | B21: SALIFOU | D21: HORS GROUPE | E21: ACHATS D 'EXPLOITATION | F21: MECANIQUE DE CAMION VERT-DEPANNAGE | H21: 45364 | I21: 400000 | J21: 45364 | M21: EN ATTENTE
A22: ROYAL LT | B22: SINERGIE RESEAU | D22: INTRA-GROUPE | E22: ACHATS D 'EXPLOITATION | F22: LOCATION ET IMPLANTATION DEC 2023-OCT 2024 | H22: 45200 | I22: 13650000 | J22: 45566 | M22: EN ATTENTE
A23: ROYAL LT | B23: SIM BETON CI | D23: INTRA-GROUPE | E23: ACHATS D 'EXPLOITATION | F23: LOCATION GRUE | H23: 45536 | I23: 6770000 | J23: 45536 | M23: EN ATTENTE
A24: ROYAL LT | B24: SIM BETON BF | D24: INTRA-GROUPE | E24: ACHATS D 'EXPLOITATION | F24: LOCATION GRUE | H24: 45566 | I24: 625000 | J24: 45566 | M24: EN ATTENTE
A25: ROYAL LT | B25: SIGIB | D25: INTRA-GROUPE | E25: ACHATS D 'EXPLOITATION | F25: LOCATION GRUE | H25: 45566 | I25: 150000 | J25: 45566 | M25: EN ATTENTE
A26: TEXTIPRINT | B26: BONAVENTURE | D26: HORS GROUPE | E26: ACHATS D 'EXPLOITATION | F26: DOCUMENT A DOS CARRE PPE 2023 | I26: 270000 | M26: EN ATTENTE
A27: TEXTIPRINT | B27: BONAVENTURE | D27: HORS GROUPE | E27: ACHATS D 'EXPLOITATION | F27: DOCUMENT A DOS CARRE PPE 0CTOBRE 2024 | I27: 145000 | M27: EN ATTENTE
A28: TEXTIPRINT | B28: SIGIB | D28: INTRA-GROUPE | E28: ACHATS D 'EXPLOITATION | F28: DETTE | I28: 1935000 | M28: EN ATTENTE
A29: TEXTIPRINT | B29: ZOUZOUA | D29: HORS GROUPE | E29: ACHATS D 'EXPLOITATION | F29: ACHAT DE BACHE 2022 | I29: 50000 | M29: EN ATTENTE
A30: TEXTIPRINT | B30: M. JD | D30: HORS GROUPE | E30: ACHATS D 'EXPLOITATION | F30: CONFECTION DE 38 TENUES MARS 2024 | I30: 150000 | M30: EN ATTENTE
A31: TEXTIPRINT | B31: GROUP HOREB | D31: HORS GROUPE | E31: ACHATS D 'EXPLOITATION | F31: IMPRESSION SUR 100 CHASUBLES SIKA M | I31: 50000 | M31: EN ATTENTE
A32: TEXTIPRINT | B32: ALYCARTOUCHE | D32: HORS GROUPE | E32: ACHATS D 'EXPLOITATION | F32: ACHAT DE BACHE FEVRIER 2024 | I32: 250000 | M32: EN ATTENTE
A33: TEXTIPRINT | B33: MALICK | D33: HORS GROUPE | E33: ACHATS D 'EXPLOITATION | F33: SOLDE CONFECTION DE SUPPORT METALLIQUE NSIA FEVRIER 2023 | I33: 30000 | M33: EN ATTENTE
A34: TEXTIPRINT | B34: WINNER PROD FIRMIN | D34: HORS GROUPE | E34: ACHATS D 'EXPLOITATION | F34: CONFECTION DE 676 PLAQUES EN PLEXIGLASS | I34: 150000 | M34: EN ATTENTE
A35: TEXTIPRINT | B35: GUIGUI ARMEL NATHAN IMPRIME | D35: HORS GROUPE | E35: ACHATS D 'EXPLOITATION | F35: CONFECTION DE 500 CALENDRIERS A3 PPE OCTOBRE 2024 | I35: 30000 | M35: EN ATTENTE
A36: TEXTIPRINT | B36: KOUAME SALOMON ET YAHIRI EMMANUEL | D36: HORS GROUPE | E36: ACHATS D 'EXPLOITATION | F36: DROITS A REVERSER | I36: 565462 | M36: EN ATTENTE
A37: SIM BETON | B37: SORO NOUHOUOLA ETIENNE | D37: INTRA-GROUPE | E37: ACHATS D 'EXPLOITATION | F37: PRÊT POUR LA PRODUCTION-RAPPORTS MENSUELS SIM BETON | I37: 2968862 | M37: EN ATTENTE
... A39: SIM BETON | B39: SORO NOUHOUOLA ETIENNE | D39: INTRA-GROUPE | E39: ACHATS D 'EXPLOITATION | F39: LOYER DU MAGASIN ANCIEN SITE | I39: 410000 | M39: EN ATTENTE
A40: =+UPPER("Total") -> TOTAL | I40: =SUBTOTAL(109,Tableau1[MONTANT TTC]) -> 61962714 | N40: =SUBTOTAL(103,Tableau1[DATE DE PAIEMENT]) -> 0

Sheet DONNEES
B2: ENTITÉ | D2: TYPE DE DETTE | E2: CAS DE FIGURE | G2: TYPE D’ INFORMATION | I2: CATEGORIE FINANCIERE | K2: ÉTAT DE LA DETTE | M2: STATUT BC | O2: TRANSACTION INTRACOMMERCIALE
B3: SIM GROUP | D3: FOURNISSEUR | E3: Facture fournisseur non encore réglée | G3: Créances Clients | I3: PRÊT BANCAIRE | K3: ÉCHU | M3: COMMANDÉ | O3: INTRA-GROUPE
B4: SINERGIE RESEAU | D4: FISCALE | E4: TVA collectée ou à reverser | G4: Dettes Fournisseurs | I4: LIGNE DE CRÉDIT | K4: À ÉCHOIR | M4: FACTURÉ | O4: HORS-GROUPE
B5: SIM BETON | D5: SOCIALE | E5: Cotisations sociales URSSAF, retraite, etc. | G5: Dettes Fiscales | I5: DÉCOUVERT BANCAIRE | M5: NON FACTURÉ
B6: ROYAL LT | D6: FINANCIÈRE-EMPRUNT | E6: Emprunt bancaire à rembourser | G6: Solde Bancaire
B7: SIGIB | D7: PERSONNEL-REMUNERATION | E7: Salaires ou primes dus | G7: Solde Caisse | K7: TAUX TVA
D8: PERSONNEL-AVANCE/REMB | E8: Avance/remboursement dû à un employé | G8: Créances Clients | K8: 0
D9: PRÊT INTERCO | E9: PRÊT ENTRE ENTITE | G9: Dettes Fournisseurs | K9: 0.09
G10: Dettes Fiscales | I10: POSTE TRESORERIE | K10: 0.18
G11: Solde Bancaire | I11: OBA
D12: TYPE D'ENGAGEMENT | G12: Solde Caisse | I12: BDU
D13: ENGAGEMENT PREVISIONNELLE | G13: Créances Clients | I13: UBA
D14: DETTE REELLE | G14: Dettes Fournisseurs | I14: GTBANK
G15: Dettes Fiscales | I15: COFINA
G16: Solde Bancaire | I16: CAISSE
D17: PERIODICITE | G17: Solde Caisse | I17: WAVE
D18: HEBDOMADAIRE | I18: ORANGE MONNEY
D19: QUINZAINE
D20: MENSUELLE
D21: BIMESTRIELLE
D22: TRIMESTRIELLE
D23: SEMESTRIELLE
D24: ANNUELLE

Sheet BASE DES ENGAGEMENTS
A1: ETAT DE LA DETTE ELARGIE
